Workbook

Sheet How to use
A1: How to use this workbook
A3: Cards tab: one row per card. Fill in the blue effect columns (I–V) with the numbers on the card; Value, Budget, Difference and Status calculate automatically.
A4: • Budget = (Cost × points per energy + base value + rarity bonus), × exhaust multiplier if the card exhausts.
A5: • Value = sum of each effect × its price (Rules tab). Power cards list their per-turn effect and are multiplied by the power multiplier.
A6: • 'Other value' is for unique effects the price list can't capture. Cards marked PLAYTEST in Notes rely on it, so balance those by playing.
A7: • Status: Balanced (within tolerance), Over budget, Under budget. Starter cards should stay under budget so every reward feels like an upgrade.
A8: • To add a card: type it into the first empty row below the set. Formulas are already there.
A10: Rules tab: baseline combat numbers, the budget formula, and the effect price list. Change any input there and the whole set re-balances.
A11: Summary tab: card counts by archetype and rarity, balance status, and the starter deck. Keywords tab: rules text for every keyword and which role implements it.
A13: Example row: C01 Slash — Attack, cost 1, Common, Damage 9 → Value 9, Budget 9, Balanced.

Sheet Rules
A1: Dungeon Roguelike – Balance Rules
A2: Blue cells on yellow are inputs: change them and every card's value/budget on the Cards tab recalculates.
A4: Baseline (combat)
A5: Player max HP | B5: 70 | C5: Starting value; tune in playtests
A6: Energy per turn | B6: 3
A7: Cards drawn per turn | B7: 5
A8: Starter deck size | B8: 10 | C8: 5 Strike, 4 Defend, 1 Lantern Bash
A9: Normal enemy HP (min) | B9: 12 | C9: Normal fights should last 3–4 turns
A10: Normal enemy HP (max) | B10: 25
A11: Elite HP (min) | B11: 40
A12: Elite HP (max) | B12: 60
A13: Boss HP | B13: 130 | C13: Single boss for v1
A15: Budget formula
A16: Points per energy | B16: 6 | C16: Budget = cost × this + base + rarity bonus
A17: Base card value | B17: 3 | C17: Being a card is worth something (draw + hand slot)
A18: Rarity bonus: Common | B18: 0
A19: Rarity bonus: Uncommon | B19: 2
A20: Rarity bonus: Rare | B20: 4
A21: Exhaust budget multiplier | B21: 1.3 | C21: One-use cards get 30% more budget
A22: Power value multiplier | B22: 2 | C22: Power effects listed per turn are worth ×2
A23: 'All enemies' multiplier | B23: 1.5 | C23: Applies to AoE damage and debuffs that hit all enemies
A24: Balanced tolerance (±) | B24: 1.5 | C24: Value within this of budget = Balanced
A26: Effect price list (points per 1)
A27: Damage | B27: 1
A28: Block | B28: 1.2 | C28: Reliable defense is slightly better than damage
A29: Heal | B29: 1.5 | C29: Healing is scarce in roguelikes; keep it pricey
A30: Draw | B30: 4
A31: Energy | B31: 6
A32: Weak (per turn) | B32: 3 | C32: Enemy deals 25% less damage
A33: Vulnerable (per turn) | B33: 3 | C33: Enemy takes 50% more damage
A34: Poison (per stack) | B34: 1.5
A35: Strength (per stack) | B35: 4 | C35: +1 damage per attack hit for the rest of the fight
A36: HP loss (per 1) | B36: 1.5 | C36: A cost to the player; subtracts value

Sheet Cards
A1: ID | B1: Name | C1: Type | D1: Cost | E1: Rarity | F1: Archetype | G1: Card text | H1: Upgraded text | I1: Damage | J1: AoE dmg | K1: Block | L1: Heal | M1: Draw | N1: Energy | O1: Weak | P1: Vuln | Q1: Poison | R1: Debuffs hit all? | S1: Strength | T1: HP loss | U1: Exhaust? | V1: Other value | W1: Notes | X1: Value | Y1: Budget | Z1: Difference | AA1: Status
A2: S01 | B2: Strike | C2: Attack | D2: 1 | E2: Starter | F2: Neutral | G2: Deal 6 damage. | H2: Deal 9 damage. | I2: 6 | W2: x5 in starter deck | X2: =ROUND((I2*Rules!$B$27+J2*Rules!$B$27*Rules!$B$23+K2*Rules!$B$28+L2*Rules!$B$29+M2*Rules!$B$30+N2*Rules!$B$31+(O2*Rules!$B$32+P2*Rules!$B$33+Q2*Rules!$B$34)*IF(R2="Y",Rules!$B$23,1)+S2*Rules!$B$35-T2*Rules!$B$36+V2)*IF(C2="Power",Rules!$B$22,1),2) -> 6 | Y2: =ROUND((D2*Rules!$B$16+Rules!$B$17+IF(E2="Uncommon",Rules!$B$19,IF(E2="Rare",Rules!$B$20,Rules!$B$18)))*IF(U2="Y",Rules!$B$21,1),2) -> 9 | Z2: =X2-Y2 -> -3 | AA2: =IF(E2="Starter",IF(Z2<0,"Starter (under on purpose)","Starter too strong"),IF(ABS(Z2)<=Rules!$B$24,"Balanced",IF(Z2>0,"Over budget","Under budget"))) -> Starter (under on purpose)
A3: S02 | B3: Defend | C3: Skill | D3: 1 | E3: Starter | F3: Neutral | G3: Gain 5 block. | H3: Gain 8 block. | K3: 5 | W3: x4 in starter deck | X3: =ROUND((I3*Rules!$B$27+J3*Rules!$B$27*Rules!$B$23+K3*Rules!$B$28+L3*Rules!$B$29+M3*Rules!$B$30+N3*Rules!$B$31+(O3*Rules!$B$32+P3*Rules!$B$33+Q3*Rules!$B$34)*IF(R3="Y",Rules!$B$23,1)+S3*Rules!$B$35-T3*Rules!$B$36+V3)*IF(C3="Power",Rules!$B$22,1),2) -> 6 | Y3: =ROUND((D3*Rules!$B$16+Rules!$B$17+IF(E3="Uncommon",Rules!$B$19,IF(E3="Rare",Rules!$B$20,Rules!$B$18)))*IF(U3="Y",Rules!$B$21,1),2) -> 9 | Z3: =X3-Y3 -> -3 | AA3: =IF(E3="Starter",IF(Z3<0,"Starter (under on purpose)","Starter too strong"),IF(ABS(Z3)<=Rules!$B$24,"Balanced",IF(Z3>0,"Over budget","Under budget"))) -> Starter (under on purpose)
A4: S03 | B4: Lantern Bash | C4: Attack | D4: 1 | E4: Starter | F4: Neutral | G4: Deal 5 damage. Apply 1 Vulnerable. | H4: Deal 7 damage. Apply 2 Vulnerable. | I4: 5 | P4: 1 | W4: x1 signature card; teaches debuffs | X4: =ROUND((I4*Rules!$B$27+J4*Rules!$B$27*Rules!$B$23+K4*Rules!$B$28+L4*Rules!$B$29+M4*Rules!$B$30+N4*Rules!$B$31+(O4*Rules!$B$32+P4*Rules!$B$33+Q4*Rules!$B$34)*IF(R4="Y",Rules!$B$23,1)+S4*Rules!$B$35-T4*Rules!$B$36+V4)*IF(C4="Power",Rules!$B$22,1),2) -> 8 | Y4: =ROUND((D4*Rules!$B$16+Rules!$B$17+IF(E4="Uncommon",Rules!$B$19,IF(E4="Rare",Rules!$B$20,Rules!$B$18)))*IF(U4="Y",Rules!$B$21,1),2) -> 9 | Z4: =X4-Y4 -> -1 | AA4: =IF(E4="Starter",IF(Z4<0,"Starter (under on purpose)","Starter too strong"),IF(ABS(Z4)<=Rules!$B$24,"Balanced",IF(Z4>0,"Over budget","Under budget"))) -> Starter (under on purpose)
A5: C01 | B5: Slash | C5: Attack | D5: 1 | E5: Common | F5: Neutral | G5: Deal 9 damage. | H5: Deal 12 damage. | I5: 9 | X5: =ROUND((I5*Rules!$B$27+J5*Rules!$B$27*Rules!$B$23+K5*Rules!$B$28+L5*Rules!$B$29+M5*Rules!$B$30+N5*Rules!$B$31+(O5*Rules!$B$32+P5*Rules!$B$33+Q5*Rules!$B$34)*IF(R5="Y",Rules!$B$23,1)+S5*Rules!$B$35-T5*Rules!$B$36+V5)*IF(C5="Power",Rules!$B$22,1),2) -> 9 | Y5: =ROUND((D5*Rules!$B$16+Rules!$B$17+IF(E5="Uncommon",Rules!$B$19,IF(E5="Rare",Rules!$B$20,Rules!$B$18)))*IF(U5="Y",Rules!$B$21,1),2) -> 9 | Z5: =X5-Y5 -> 0 | AA5: =IF(E5="Starter",IF(Z5<0,"Starter (under on purpose)","Starter too strong"),IF(ABS(Z5)<=Rules!$B$24,"Balanced",IF(Z5>0,"Over budget","Under budget"))) -> Balanced
A6: C02 | B6: Quick Jab | C6: Attack | D6: 0 | E6: Common | F6: Brawler | G6: Deal 3 damage. | H6: Deal 5 damage. | I6: 3 | W6: Free attacks scale with Strength | X6: =ROUND((I6*Rules!$B$27+J6*Rules!$B$27*Rules!$B$23+K6*Rules!$B$28+L6*Rules!$B$29+M6*Rules!$B$30+N6*Rules!$B$31+(O6*Rules!$B$32+P6*Rules!$B$33+Q6*Rules!$B$34)*IF(R6="Y",Rules!$B$23,1)+S6*Rules!$B$35-T6*Rules!$B$36+V6)*IF(C6="Power",Rules!$B$22,1),2) -> 3 | Y6: =ROUND((D6*Rules!$B$16+Rules!$B$17+IF(E6="Uncommon",Rules!$B$19,IF(E6="Rare",Rules!$B$20,Rules!$B$18)))*IF(U6="Y",Rules!$B$21,1),2) -> 3 | Z6: =X6-Y6 -> 0 | AA6: =IF(E6="Starter",IF(Z6<0,"Starter (under on purpose)","Starter too strong"),IF(ABS(Z6)<=Rules!$B$24,"Balanced",IF(Z6>0,"Over budget","Under budget"))) -> Balanced
A7: C03 | B7: Cleave | C7: Attack | D7: 1 | E7: Common | F7: Neutral | G7: Deal 6 damage to ALL enemies. | H7: Deal 9 damage to ALL enemies. | J7: 6 | X7: =ROUND((I7*Rules!$B$27+J7*Rules!$B$27*Rules!$B$23+K7*Rules!$B$28+L7*Rules!$B$29+M7*Rules!$B$30+N7*Rules!$B$31+(O7*Rules!$B$32+P7*Rules!$B$33+Q7*Rules!$B$34)*IF(R7="Y",Rules!$B$23,1)+S7*Rules!$B$35-T7*Rules!$B$36+V7)*IF(C7="Power",Rules!$B$22,1),2) -> 9 | Y7: =ROUND((D7*Rules!$B$16+Rules!$B$17+IF(E7="Uncommon",Rules!$B$19,IF(E7="Rare",Rules!$B$20,Rules!$B$18)))*IF(U7="Y",Rules!$B$21,1),2) -> 9 | Z7: =X7-Y7 -> 0 | AA7: =IF(E7="Starter",IF(Z7<0,"Starter (under on purpose)","Starter too strong"),IF(ABS(Z7)<=Rules!$B$24,"Balanced",IF(Z7>0,"Over budget","Under budget"))) -> Balanced
A8: C04 | B8: Heavy Swing | C8: Attack | D8: 2 | E8: Common | F8: Brawler | G8: Deal 15 damage. | H8: Deal 20 damage. | I8: 15 | X8: =ROUND((I8*Rules!$B$27+J8*Rules!$B$27*Rules!$B$23+K8*Rules!$B$28+L8*Rules!$B$29+M8*Rules!$B$30+N8*Rules!$B$31+(O8*Rules!$B$32+P8*Rules!$B$33+Q8*Rules!$B$34)*IF(R8="Y",Rules!$B$23,1)+S8*Rules!$B$35-T8*Rules!$B$36+V8)*IF(C8="Power",Rules!$B$22,1),2) -> 15 | Y8: =ROUND((D8*Rules!$B$16+Rules!$B$17+IF(E8="Uncommon",Rules!$B$19,IF(E8="Rare",Rules!$B$20,Rules!$B$18)))*IF(U8="Y",Rules!$B$21,1),2) -> 15 | Z8: =X8-Y8 -> 0 | AA8: =IF(E8="Starter",IF(Z8<0,"Starter (under on purpose)","Starter too strong"),IF(ABS(Z8)<=Rules!$B$24,"Balanced",IF(Z8>0,"Over budget","Under budget"))) -> Balanced
A9: C05 | B9: Twin Strike | C9: Attack | D9: 1 | E9: Common | F9: Brawler | G9: Deal 4 damage twice. | H9: Deal 5 damage twice. | I9: 8 | V9: 1 | W9: Other: multi-hit doubles Strength bonus | X9: =ROUND((I9*Rules!$B$27+J9*Rules!$B$27*Rules!$B$23+K9*Rules!$B$28+L9*Rules!$B$29+M9*Rules!$B$30+N9*Rules!$B$31+(O9*Rules!$B$32+P9*Rules!$B$33+Q9*Rules!$B$34)*IF(R9="Y",Rules!$B$23,1)+S9*Rules!$B$35-T9*Rules!$B$36+V9)*IF(C9="Power",Rules!$B$22,1),2) -> 9 | Y9: =ROUND((D9*Rules!$B$16+Rules!$B$17+IF(E9="Uncommon",Rules!$B$19,IF(E9="Rare",Rules!$B$20,Rules!$B$18)))*IF(U9="Y",Rules!$B$21,1),2) -> 9 | Z9: =X9-Y9 -> 0 | AA9: =IF(E9="Starter",IF(Z9<0,"Starter (under on purpose)","Starter too strong"),IF(ABS(Z9)<=Rules!$B$24,"Balanced",IF(Z9>0,"Over budget","Under budget"))) -> Balanced
A10: C06 | B10: Poisoned Blade | C10: Attack | D10: 1 | E10: Common | F10: Venom | G10: Deal 3 damage. Apply 4 Poison. | H10: Deal 4 damage. Apply 6 Poison. | I10: 3 | Q10: 4 | X10: =ROUND((I10*Rules!$B$27+J10*Rules!$B$27*Rules!$B$23+K10*Rules!$B$28+L10*Rules!$B$29+M10*Rules!$B$30+N10*Rules!$B$31+(O10*Rules!$B$32+P10*Rules!$B$33+Q10*Rules!$B$34)*IF(R10="Y",Rules!$B$23,1)+S10*Rules!$B$35-T10*Rules!$B$36+V10)*IF(C10="Power",Rules!$B$22,1),2) -> 9 | Y10: =ROUND((D10*Rules!$B$16+Rules!$B$17+IF(E10="Uncommon",Rules!$B$19,IF(E10="Rare",Rules!$B$20,Rules!$B$18)))*IF(U10="Y",Rules!$B$21,1),2) -> 9 | Z10: =X10-Y10 -> 0 | AA10: =IF(E10="Starter",IF(Z10<0,"Starter (under on purpose)","Starter too strong"),IF(ABS(Z10)<=Rules!$B$24,"Balanced",IF(Z10>0,"Over budget","Under budget"))) -> Balanced
A11: C07 | B11: Shield Slam | C11: Attack | D11: 1 | E11: Common | F11: Guardian | G11: Deal 4 damage. Gain 4 block. | H11: Deal 6 damage. Gain 6 block. | I11: 4 | K11: 4 | X11: =ROUND((I11*Rules!$B$27+J11*Rules!$B$27*Rules!$B$23+K11*Rules!$B$28+L11*Rules!$B$29+M11*Rules!$B$30+N11*Rules!$B$31+(O11*Rules!$B$32+P11*Rules!$B$33+Q11*Rules!$B$34)*IF(R11="Y",Rules!$B$23,1)+S11*Rules!$B$35-T11*Rules!$B$36+V11)*IF(C11="Power",Rules!$B$22,1),2) -> 8.8 | Y11: =ROUND((D11*Rules!$B$16+Rules!$B$17+IF(E11="Uncommon",Rules!$B$19,IF(E11="Rare",Rules!$B$20,Rules!$B$18)))*IF(U11="Y",Rules!$B$21,1),2) -> 9 | Z11: =X11-Y11 -> -0.2 | AA11: =IF(E11="Starter",IF(Z11<0,"Starter (under on purpose)","Starter too strong"),IF(ABS(Z11)<=Rules!$B$24,"Balanced",IF(Z11>0,"Over budget","Under budget"))) -> Balanced
A12: C08 | B12: Venom Fang | C12: Skill | D12: 0 | E12: Common | F12: Venom | G12: Apply 2 Poison. | H12: Apply 3 Poison. | Q12: 2 | X12: =ROUND((I12*Rules!$B$27+J12*Rules!$B$27*Rules!$B$23+K12*Rules!$B$28+L12*Rules!$B$29+M12*Rules!$B$30+N12*Rules!$B$31+(O12*Rules!$B$32+P12*Rules!$B$33+Q12*Rules!$B$34)*IF(R12="Y",Rules!$B$23,1)+S12*Rules!$B$35-T12*Rules!$B$36+V12)*IF(C12="Power",Rules!$B$22,1),2) -> 3 | Y12: =ROUND((D12*Rules!$B$16+Rules!$B$17+IF(E12="Uncommon",Rules!$B$19,IF(E12="Rare",Rules!$B$20,Rules!$B$18)))*IF(U12="Y",Rules!$B$21,1),2) -> 3 | Z12: =X12-Y12 -> 0 | AA12: =IF(E12="Starter",IF(Z12<0,"Starter (under on purpose)","Starter too strong"),IF(ABS(Z12)<=Rules!$B$24,"Balanced",IF(Z12>0,"Over budget","Under budget"))) -> Balanced
A13: C09 | B13: Pommel Strike | C13: Attack | D13: 1 | E13: Common | F13: Tactician | G13: Deal 5 damage. Draw 1 card. | H13: Deal 7 damage. Draw 1 card. | I13: 5 | M13: 1 | X13: =ROUND((I13*Rules!$B$27+J13*Rules!$B$27*Rules!$B$23+K13*Rules!$B$28+L13*Rules!$B$29+M13*Rules!$B$30+N13*Rules!$B$31+(O13*Rules!$B$32+P13*Rules!$B$33+Q13*Rules!$B$34)*IF(R13="Y",Rules!$B$23,1)+S13*Rules!$B$35-T13*Rules!$B$36+V13)*IF(C13="Power",Rules!$B$22,1),2) -> 9 | Y13: =ROUND((D13*Rules!$B$16+Rules!$B$17+IF(E13="Uncommon",Rules!$B$19,IF(E13="Rare",Rules!$B$20,Rules!$B$18)))*IF(U13="Y",Rules!$B$21,1),2) -> 9 | Z13: =X13-Y13 -> 0 | AA13: =IF(E13="Starter",IF(Z13<0,"Starter (under on purpose)","Starter too strong"),IF(ABS(Z13)<=Rules!$B$24,"Balanced",IF(Z13>0,"Over budget","Under budget"))) -> Balanced
A14: C10 | B14: Torch Swing | C14: Attack | D14: 1 | E14: Common | F14: Tactician | G14: Deal 6 damage. Apply 1 Vulnerable. | H14: Deal 8 damage. Apply 2 Vulnerable. | I14: 6 | P14: 1 | X14: =ROUND((I14*Rules!$B$27+J14*Rules!$B$27*Rules!$B$23+K14*Rules!$B$28+L14*Rules!$B$29+M14*Rules!$B$30+N14*Rules!$B$31+(O14*Rules!$B$32+P14*Rules!$B$33+Q14*Rules!$B$34)*IF(R14="Y",Rules!$B$23,1)+S14*Rules!$B$35-T14*Rules!$B$36+V14)*IF(C14="Power",Rules!$B$22,1),2) -> 9 | Y14: =ROUND((D14*Rules!$B$16+Rules!$B$17+IF(E14="Uncommon",Rules!$B$19,IF(E14="Rare",Rules!$B$20,Rules!$B$18)))*IF(U14="Y",Rules!$B$21,1),2) -> 9 | Z14: =X14-Y14 -> 0 | AA14: =IF(E14="Starter",IF(Z14<0,"Starter (under on purpose)","Starter too strong"),IF(ABS(Z14)<=Rules!$B$24,"Balanced",IF(Z14>0,"Over budget","Under budget"))) -> Balanced
A15: C11 | B15: Brace | C15: Skill | D15: 1 | E15: Common | F15: Guardian | G15: Gain 7 block. | H15: Gain 10 block. | K15: 7 | X15: =ROUND((I15*Rules!$B$27+J15*Rules!$B$27*Rules!$B$23+K15*Rules!$B$28+L15*Rules!$B$29+M15*Rules!$B$30+N15*Rules!$B$31+(O15*Rules!$B$32+P15*Rules!$B$33+Q15*Rules!$B$34)*IF(R15="Y",Rules!$B$23,1)+S15*Rules!$B$35-T15*Rules!$B$36+V15)*IF(C15="Power",Rules!$B$22,1),2) -> 8.4 | Y15: =ROUND((D15*Rules!$B$16+Rules!$B$17+IF(E15="Uncommon",Rules!$B$19,IF(E15="Rare",Rules!$B$20,Rules!$B$18)))*IF(U15="Y",Rules!$B$21,1),2) -> 9 | Z15: =X15-Y15 -> -0.6 | AA15: =IF(E15="Starter",IF(Z15<0,"Starter (under on purpose)","Starter too strong"),IF(ABS(Z15)<=Rules!$B$24,"Balanced",IF(Z15>0,"Over budget","Under budget"))) -> Balanced
A16: C12 | B16: Raise Shield | C16: Skill | D16: 2 | E16: Common | F16: Guardian | G16: Gain 12 block. | H16: Gain 16 block. | K16: 12 | X16: =ROUND((I16*Rules!$B$27+J16*Rules!$B$27*Rules!$B$23+K16*Rules!$B$28+L16*Rules!$B$29+M16*Rules!$B$30+N16*Rules!$B$31+(O16*Rules!$B$32+P16*Rules!$B$33+Q16*Rules!$B$34)*IF(R16="Y",Rules!$B$23,1)+S16*Rules!$B$35-T16*Rules!$B$36+V16)*IF(C16="Power",Rules!$B$22,1),2) -> 14.4 | Y16: =ROUND((D16*Rules!$B$16+Rules!$B$17+IF(E16="Uncommon",Rules!$B$19,IF(E16="Rare",Rules!$B$20,Rules!$B$18)))*IF(U16="Y",Rules!$B$21,1),2) -> 15 | Z16: =X16-Y16 -> -0.6 | AA16: =IF(E16="Starter",IF(Z16<0,"Starter (under on purpose)","Starter too strong"),IF(ABS(Z16)<=Rules!$B$24,"Balanced",IF(Z16>0,"Over budget","Under budget"))) -> Balanced
A17: C13 | B17: Dodge Roll | C17: Skill | D17: 1 | E17: Common | F17: Guardian | G17: Gain 4 block. Draw 1 card. | H17: Gain 6 block. Draw 1 card. | K17: 4 | M17: 1 | X17: =ROUND((I17*Rules!$B$27+J17*Rules!$B$27*Rules!$B$23+K17*Rules!$B$28+L17*Rules!$B$29+M17*Rules!$B$30+N17*Rules!$B$31+(O17*Rules!$B$32+P17*Rules!$B$33+Q17*Rules!$B$34)*IF(R17="Y",Rules!$B$23,1)+S17*Rules!$B$35-T17*Rules!$B$36+V17)*IF(C17="Power",Rules!$B$22,1),2) -> 8.8 | Y17: =ROUND((D17*Rules!$B$16+Rules!$B$17+IF(E17="Uncommon",Rules!$B$19,IF(E17="Rare",Rules!$B$20,Rules!$B$18)))*IF(U17="Y",Rules!$B$21,1),2) -> 9 | Z17: =X17-Y17 -> -0.2 | AA17: =IF(E17="Starter",IF(Z17<0,"Starter (under on purpose)","Starter too strong"),IF(ABS(Z17)<=Rules!$B$24,"Balanced",IF(Z17>0,"Over budget","Under budget"))) -> Balanced
A18: C14 | B18: Toxic Vial | C18: Skill | D18: 1 | E18: Common | F18: Venom | G18: Apply 6 Poison. | H18: Apply 9 Poison. | Q18: 6 | X18: =ROUND((I18*Rules!$B$27+J18*Rules!$B$27*Rules!$B$23+K18*Rules!$B$28+L18*Rules!$B$29+M18*Rules!$B$30+N18*Rules!$B$31+(O18*Rules!$B$32+P18*Rules!$B$33+Q18*Rules!$B$34)*IF(R18="Y",Rules!$B$23,1)+S18*Rules!$B$35-T18*Rules!$B$36+V18)*IF(C18="Power",Rules!$B$22,1),2) -> 9 | Y18: =ROUND((D18*Rules!$B$16+Rules!$B$17+IF(E18="Uncommon",Rules!$B$19,IF(E18="Rare",Rules!$B$20,Rules!$B$18)))*IF(U18="Y",Rules!$B$21,1),2) -> 9 | Z18: =X18-Y18 -> 0 | AA18: =IF(E18="Starter",IF(Z18<0,"Starter (under on purpose)","Starter too strong"),IF(ABS(Z18)<=Rules!$B$24,"Balanced",IF(Z18>0,"Over budget","Under budget"))) -> Balanced
A19: C15 | B19: Bandage | C19: Skill | D19: 1 | E19: Common | F19: Neutral | G19: Gain 4 block. Heal 4 HP. Exhaust. | H19: Gain 5 block. Heal 6 HP. Exhaust. | K19: 4 | L19: 4 | U19: Y | W19: Only in-combat heal at Common | X19: =ROUND((I19*Rules!$B$27+J19*Rules!$B$27*Rules!$B$23+K19*Rules!$B$28+L19*Rules!$B$29+M19*Rules!$B$30+N19*Rules!$B$31+(O19*Rules!$B$32+P19*Rules!$B$33+Q19*Rules!$B$34)*IF(R19="Y",Rules!$B$23,1)+S19*Rules!$B$35-T19*Rules!$B$36+V19)*IF(C19="Power",Rules!$B$22,1),2) -> 10.8 | Y19: =ROUND((D19*Rules!$B$16+Rules!$B$17+IF(E19="Uncommon",Rules!$B$19,IF(E19="Rare",Rules!$B$20,Rules!$B$18)))*IF(U19="Y",Rules!$B$21,1),2) -> 11.7 | Z19: =X19-Y19 -> -0.9 | AA19: =IF(E19="Starter",IF(Z19<0,"Starter (under on purpose)","Starter too strong"),IF(ABS(Z19)<=Rules!$B$24,"Balanced",IF(Z19>0,"Over budget","Under budget"))) -> Balanced
A20: C16 | B20: Scout Ahead | C20: Skill | D20: 1 | E20: Common | F20: Tactician | G20: Draw 2 cards. | H20: Draw 3 cards. | M20: 2 | X20: =ROUND((I20*Rules!$B$27+J20*Rules!$B$27*Rules!$B$23+K20*Rules!$B$28+L20*Rules!$B$29+M20*Rules!$B$30+N20*Rules!$B$31+(O20*Rules!$B$32+P20*Rules!$B$33+Q20*Rules!$B$34)*IF(R20="Y",Rules!$B$23,1)+S20*Rules!$B$35-T20*Rules!$B$36+V20)*IF(C20="Power",Rules!$B$22,1),2) -> 8 | Y20: =ROUND((D20*Rules!$B$16+Rules!$B$17+IF(E20="Uncommon",Rules!$B$19,IF(E20="Rare",Rules!$B$20,Rules!$B$18)))*IF(U20="Y",Rules!$B$21,1),2) -> 9 | Z20: =X20-Y20 -> -1 | AA20: =IF(E20="Starter",IF(Z20<0,"Starter (under on purpose)","Starter too strong"),IF(ABS(Z20)<=Rules!$B$24,"Balanced",IF(Z20>0,"Over budget","Under budget"))) -> Balanced
A21: C17 | B21: Smoke Bomb | C21: Skill | D21: 1 | E21: Common | F21: Tactician | G21: Apply 2 Weak to ALL enemies. | H21: Apply 3 Weak to ALL enemies. | O21: 2 | R21: Y | X21: =ROUND((I21*Rules!$B$27+J21*Rules!$B$27*Rules!$B$23+K21*Rules!$B$28+L21*Rules!$B$29+M21*Rules!$B$30+N21*Rules!$B$31+(O21*Rules!$B$32+P21*Rules!$B$33+Q21*Rules!$B$34)*IF(R21="Y",Rules!$B$23,1)+S21*Rules!$B$35-T21*Rules!$B$36+V21)*IF(C21="Power",Rules!$B$22,1),2) -> 9 | Y21: =ROUND((D21*Rules!$B$16+Rules!$B$17+IF(E21="Uncommon",Rules!$B$19,IF(E21="Rare",Rules!$B$20,Rules!$B$18)))*IF(U21="Y",Rules!$B$21,1),2) -> 9 | Z21: =X21-Y21 -> 0 | AA21: =IF(E21="Starter",IF(Z21<0,"Starter (under on purpose)","Starter too strong"),IF(ABS(Z21)<=Rules!$B$24,"Balanced",IF(Z21>0,"Over budget","Under budget"))) -> Balanced
A22: C18 | B22: Sharpen | C22: Skill | D22: 0 | E22: Common | F22: Brawler | G22: Your next Attack this turn deals 3 extra damage. | H22: Your next Attack this turn deals 5 extra damage. | V22: 3 | W22: Other: conditional +3 damage | X22: =ROUND((I22*Rules!$B$27+J22*Rules!$B$27*Rules!$B$23+K22*Rules!$B$28+L22*Rules!$B$29+M22*Rules!$B$30+N22*Rules!$B$31+(O22*Rules!$B$32+P22*Rules!$B$33+Q22*Rules!$B$34)*IF(R22="Y",Rules!$B$23,1)+S22*Rules!$B$35-T22*Rules!$B$36+V22)*IF(C22="Power",Rules!$B$22,1),2) -> 3 | Y22: =ROUND((D22*Rules!$B$16+Rules!$B$17+IF(E22="Uncommon",Rules!$B$19,IF(E22="Rare",Rules!$B$20,Rules!$B$18)))*IF(U22="Y",Rules!$B$21,1),2) -> 3 | Z22: =X22-Y22 -> 0 | AA22: =IF(E22="Starter",IF(Z22<0,"Starter (under on purpose)","Starter too strong"),IF(ABS(Z22)<=Rules!$B$24,"Balanced",IF(Z22>0,"Over budget","Under budget"))) -> Balanced
A23: C19 | B23: Deep Breath | C23: Skill | D23: 0 | E23: Common | F23: Tactician | G23: Draw 1 card. Exhaust. | H23: Draw 2 cards. Exhaust. | M23: 1 | U23: Y | X23: =ROUND((I23*Rules!$B$27+J23*Rules!$B$27*Rules!$B$23+K23*Rules!$B$28+L23*Rules!$B$29+M23*Rules!$B$30+N23*Rules!$B$31+(O23*Rules!$B$32+P23*Rules!$B$33+Q23*Rules!$B$34)*IF(R23="Y",Rules!$B$23,1)+S23*Rules!$B$35-T23*Rules!$B$36+V23)*IF(C23="Power",Rules!$B$22,1),2) -> 4 | Y23: =ROUND((D23*Rules!$B$16+Rules!$B$17+IF(E23="Uncommon",Rules!$B$19,IF(E23="Rare",Rules!$B$20,Rules!$B$18)))*IF(U23="Y",Rules!$B$21,1),2) -> 3.9 | Z23: =X23-Y23 -> 0.1 | AA23: =IF(E23="Starter",IF(Z23<0,"Starter (under on purpose)","Starter too strong"),IF(ABS(Z23)<=Rules!$B$24,"Balanced",IF(Z23>0,"Over budget","Under budget"))) -> Balanced
A24: C20 | B24: Stand Firm | C24: Skill | D24: 1 | E24: Common | F24: Guardian | G24: Gain 5 block. Apply 1 Weak. | H24: Gain 7 block. Apply 1 Weak. | K24: 5 | O24: 1 | X24: =ROUND((I24*Rules!$B$27+J24*Rules!$B$27*Rules!$B$23+K24*Rules!$B$28+L24*Rules!$B$29+M24*Rules!$B$30+N24*Rules!$B$31+(O24*Rules!$B$32+P24*Rules!$B$33+Q24*Rules!$B$34)*IF(R24="Y",Rules!$B$23,1)+S24*Rules!$B$35-T24*Rules!$B$36+V24)*IF(C24="Power",Rules!$B$22,1),2) -> 9 | Y24: =ROUND((D24*Rules!$B$16+Rules!$B$17+IF(E24="Uncommon",Rules!$B$19,IF(E24="Rare",Rules!$B$20,Rules!$B$18)))*IF(U24="Y",Rules!$B$21,1),2) -> 9 | Z24: =X24-Y24 -> 0 | AA24: =IF(E24="Starter",IF(Z24<0,"Starter (under on purpose)","Starter too strong"),IF(ABS(Z24)<=Rules!$B$24,"Balanced",IF(Z24>0,"Over budget","Under budget"))) -> Balanced
A25: U01 | B25: Expose | C25: Attack | D25: 1 | E25: Uncommon | F25: Tactician | G25: Deal 5 damage. Apply 2 Vulnerable. | H25: Deal 7 damage. Apply 3 Vulnerable. | I25: 5 | P25: 2 | X25: =ROUND((I25*Rules!$B$27+J25*Rules!$B$27*Rules!$B$23+K25*Rules!$B$28+L25*Rules!$B$29+M25*Rules!$B$30+N25*Rules!$B$31+(O25*Rules!$B$32+P25*Rules!$B$33+Q25*Rules!$B$34)*IF(R25="Y",Rules!$B$23,1)+S25*Rules!$B$35-T25*Rules!$B$36+V25)*IF(C25="Power",Rules!$B$22,1),2) -> 11 | Y25: =ROUND((D25*Rules!$B$16+Rules!$B$17+IF(E25="Uncommon",Rules!$B$19,IF(E25="Rare",Rules!$B$20,Rules!$B$18)))*IF(U25="Y",Rules!$B$21,1),2) -> 11 | Z25: =X25-Y25 -> 0 | AA25: =IF(E25="Starter",IF(Z25<0,"Starter (under on purpose)","Starter too strong"),IF(ABS(Z25)<=Rules!$B$24,"Balanced",IF(Z25>0,"Over budget","Under budget"))) -> Balanced
A26: U02 | B26: Shield Bash | C26: Attack | D26: 2 | E26: Uncommon | F26: Guardian | G26: Deal 8 damage. Gain 7 block. | H26: Deal 11 damage. Gain 9 block. | I26: 8 | K26: 7 | X26: =ROUND((I26*Rules!$B$27+J26*Rules!$B$27*Rules!$B$23+K26*Rules!$B$28+L26*Rules!$B$29+M26*Rules!$B$30+N26*Rules!$B$31+(O26*Rules!$B$32+P26*Rules!$B$33+Q26*Rules!$B$34)*IF(R26="Y",Rules!$B$23,1)+S26*Rules!$B$35-T26*Rules!$B$36+V26)*IF(C26="Power",Rules!$B$22,1),2) -> 16.4 | Y26: =ROUND((D26*Rules!$B$16+Rules!$B$17+IF(E26="Uncommon",Rules!$B$19,IF(E26="Rare",Rules!$B$20,Rules!$B$18)))*IF(U26="Y",Rules!$B$21,1),2) -> 17 | Z26: =X26-Y26 -> -0.6 | AA26: =IF(E26="Starter",IF(Z26<0,"Starter (under on purpose)","Starter too strong"),IF(ABS(Z26)<=Rules!$B$24,"Balanced",IF(Z26>0,"Over budget","Under budget"))) -> Balanced
A27: U03 | B27: Whirling Blade | C27: Attack | D27: 2 | E27: Uncommon | F27: Brawler | G27: Deal 11 damage to ALL enemies. | H27: Deal 15 damage to ALL enemies. | J27: 11 | X27: =ROUND((I27*Rules!$B$27+J27*Rules!$B$27*Rules!$B$23+K27*Rules!$B$28+L27*Rules!$B$29+M27*Rules!$B$30+N27*Rules!$B$31+(O27*Rules!$B$32+P27*Rules!$B$33+Q27*Rules!$B$34)*IF(R27="Y",Rules!$B$23,1)+S27*Rules!$B$35-T27*Rules!$B$36+V27)*IF(C27="Power",Rules!$B$22,1),2) -> 16.5 | Y27: =ROUND((D27*Rules!$B$16+Rules!$B$17+IF(E27="Uncommon",Rules!$B$19,IF(E27="Rare",Rules!$B$20,Rules!$B$18)))*IF(U27="Y",Rules!$B$21,1),2) -> 17 | Z27: =X27-Y27 -> -0.5 | AA27: =IF(E27="Starter",IF(Z27<0,"Starter (under on purpose)","Starter too strong"),IF(ABS(Z27)<=Rules!$B$24,"Balanced",IF(Z27>0,"Over budget","Under budget"))) -> Balanced
A28: U04 | B28: Venom Cloud | C28: Skill | D28: 2 | E28: Uncommon | F28: Venom | G28: Apply 7 Poison to ALL enemies. | H28: Apply 10 Poison to ALL enemies. | Q28: 7 | R28: Y | X28: =ROUND((I28*Rules!$B$27+J28*Rules!$B$27*Rules!$B$23+K28*Rules!$B$28+L28*Rules!$B$29+M28*Rules!$B$30+N28*Rules!$B$31+(O28*Rules!$B$32+P28*Rules!$B$33+Q28*Rules!$B$34)*IF(R28="Y",Rules!$B$23,1)+S28*Rules!$B$35-T28*Rules!$B$36+V28)*IF(C28="Power",Rules!$B$22,1),2) -> 15.75 | Y28: =ROUND((D28*Rules!$B$16+Rules!$B$17+IF(E28="Uncommon",Rules!$B$19,IF(E28="Rare",Rules!$B$20,Rules!$B$18)))*IF(U28="Y",Rules!$B$21,1),2) -> 17 | Z28: =X28-Y28 -> -1.25 | AA28: =IF(E28="Starter",IF(Z28<0,"Starter (under on purpose)","Starter too strong"),IF(ABS(Z28)<=Rules!$B$24,"Balanced",IF(Z28>0,"Over budget","Under budget"))) -> Balanced
A29: U05 | B29: Rally | C29: Skill | D29: 0 | E29: Uncommon | F29: Tactician | G29: Gain 1 energy. Exhaust. | H29: Gain 1 energy. Draw 1 card. Exhaust. | N29: 1 | U29: Y | X29: =ROUND((I29*Rules!$B$27+J29*Rules!$B$27*Rules!$B$23+K29*Rules!$B$28+L29*Rules!$B$29+M29*Rules!$B$30+N29*Rules!$B$31+(O29*Rules!$B$32+P29*Rules!$B$33+Q29*Rules!$B$34)*IF(R29="Y",Rules!$B$23,1)+S29*Rules!$B$35-T29*Rules!$B$36+V29)*IF(C29="Power",Rules!$B$22,1),2) -> 6 | Y29: =ROUND((D29*Rules!$B$16+Rules!$B$17+IF(E29="Uncommon",Rules!$B$19,IF(E29="Rare",Rules!$B$20,Rules!$B$18)))*IF(U29="Y",Rules!$B$21,1),2) -> 6.5 | Z29: =X29-Y29 -> -0.5 | AA29: =IF(E29="Starter",IF(Z29<0,"Starter (under on purpose)","Starter too strong"),IF(ABS(Z29)<=Rules!$B$24,"Balanced",IF(Z29>0,"Over budget","Under budget"))) -> Balanced
A30: U06 | B30: Iron Skin | C30: Power | D30: 1 | E30: Uncommon | F30: Guardian | G30: At the start of each turn, gain 4 block. | H30: At the start of each turn, gain 6 block. | K30: 4 | W30: Power: per-turn effect | X30: =ROUND((I30*Rules!$B$27+J30*Rules!$B$27*Rules!$B$23+K30*Rules!$B$28+L30*Rules!$B$29+M30*Rules!$B$30+N30*Rules!$B$31+(O30*Rules!$B$32+P30*Rules!$B$33+Q30*Rules!$B$34)*IF(R30="Y",Rules!$B$23,1)+S30*Rules!$B$35-T30*Rules!$B$36+V30)*IF(C30="Power",Rules!$B$22,1),2) -> 9.6 | Y30: =ROUND((D30*Rules!$B$16+Rules!$B$17+IF(E30="Uncommon",Rules!$B$19,IF(E30="Rare",Rules!$B$20,Rules!$B$18)))*IF(U30="Y",Rules!$B$21,1),2) -> 11 | Z30: =X30-Y30 -> -1.4 | AA30: =IF(E30="Starter",IF(Z30<0,"Starter (under on purpose)","Starter too strong"),IF(ABS(Z30)<=Rules!$B$24,"Balanced",IF(Z30>0,"Over budget","Under budget"))) -> Balanced
A31: U07 | B31: Battle Cry | C31: Skill | D31: 1 | E31: Uncommon | F31: Brawler | G31: Gain 2 Strength. Draw 1 card. | H31: Gain 3 Strength. Draw 1 card. | M31: 1 | S31: 2 | W31: Core Brawler engine | X31: =ROUND((I31*Rules!$B$27+J31*Rules!$B$27*Rules!$B$23+K31*Rules!$B$28+L31*Rules!$B$29+M31*Rules!$B$30+N31*Rules!$B$31+(O31*Rules!$B$32+P31*Rules!$B$33+Q31*Rules!$B$34)*IF(R31="Y",Rules!$B$23,1)+S31*Rules!$B$35-T31*Rules!$B$36+V31)*IF(C31="Power",Rules!$B$22,1),2) -> 12 | Y31: =ROUND((D31*Rules!$B$16+Rules!$B$17+IF(E31="Uncommon",Rules!$B$19,IF(E31="Rare",Rules!$B$20,Rules!$B$18)))*IF(U31="Y",Rules!$B$21,1),2) -> 11 | Z31: =X31-Y31 -> 1 | AA31: =IF(E31="Starter",IF(Z31<0,"Starter (under on purpose)","Starter too strong"),IF(ABS(Z31)<=Rules!$B$24,"Balanced",IF(Z31>0,"Over budget","Under budget"))) -> Balanced
A32: U08 | B32: Bloodletter | C32: Attack | D32: 2 | E32: Uncommon | F32: Brawler | G32: Deal 12 damage. If this kills an enemy, heal 5 HP. | H32: Deal 15 damage. If this kills an enemy, heal 7 HP. | I32: 12 | V32: 4 | W32: Other: conditional heal (~half of 5 heal) | X32: =ROUND((I32*Rules!$B$27+J32*Rules!$B$27*Rules!$B$23+K32*Rules!$B$28+L32*Rules!$B$29+M32*Rules!$B$30+N32*Rules!$B$31+(O32*Rules!$B$32+P32*Rules!$B$33+Q32*Rules!$B$34)*IF(R32="Y",Rules!$B$23,1)+S32*Rules!$B$35-T32*Rules!$B$36+V32)*IF(C32="Power",Rules!$B$22,1),2) -> 16 | Y32: =ROUND((D32*Rules!$B$16+Rules!$B$17+IF(E32="Uncommon",Rules!$B$19,IF(E32="Rare",Rules!$B$20,Rules!$B$18)))*IF(U32="Y",Rules!$B$21,1),2) -> 17 | Z32: =X32-Y32 -> -1 | AA32: =IF(E32="Starter",IF(Z32<0,"Starter (under on purpose)","Starter too strong"),IF(ABS(Z32)<=Rules!$B$24,"Balanced",IF(Z32>0,"Over budget","Under budget"))) -> Balanced
A33: U09 | B33: Envenom | C33: Power | D33: 1 | E33: Uncommon | F33: Venom | G33: Whenever your Attack deals damage, apply 1 Poison. | H33: Whenever your Attack deals damage, apply 2 Poison. | V33: 5.5 | W33: PLAYTEST: value depends on attacks per turn | X33: =ROUND((I33*Rules!$B$27+J33*Rules!$B$27*Rules!$B$23+K33*Rules!$B$28+L33*Rules!$B$29+M33*Rules!$B$30+N33*Rules!$B$31+(O33*Rules!$B$32+P33*Rules!$B$33+Q33*Rules!$B$34)*IF(R33="Y",Rules!$B$23,1)+S33*Rules!$B$35-T33*Rules!$B$36+V33)*IF(C33="Power",Rules!$B$22,1),2) -> 11 | Y33: =ROUND((D33*Rules!$B$16+Rules!$B$17+IF(E33="Uncommon",Rules!$B$19,IF(E33="Rare",Rules!$B$20,Rules!$B$18)))*IF(U33="Y",Rules!$B$21,1),2) -> 11 | Z33: =X33-Y33 -> 0 | AA33: =IF(E33="Starter",IF(Z33<0,"Starter (under on purpose)","Starter too strong"),IF(ABS(Z33)<=Rules!$B$24,"Balanced",IF(Z33>0,"Over budget","Under budget"))) -> Balanced
A34: U10 | B34: Parry | C34: Skill | D34: 1 | E34: Uncommon | F34: Guardian | G34: Gain 6 block. If the enemy intends to attack, deal 5 damage to it. | H34: Gain 8 block. If the enemy intends to attack, deal 8 damage to it. | K34: 6 | V34: 3.5 | W34: Uses enemy intent (Role 1) | X34: =ROUND((I34*Rules!$B$27+J34*Rules!$B$27*Rules!$B$23+K34*Rules!$B$28+L34*Rules!$B$29+M34*Rules!$B$30+N34*Rules!$B$31+(O34*Rules!$B$32+P34*Rules!$B$33+Q34*Rules!$B$34)*IF(R34="Y",Rules!$B$23,1)+S34*Rules!$B$35-T34*Rules!$B$36+V34)*IF(C34="Power",Rules!$B$22,1),2) -> 10.7 | Y34: =ROUND((D34*Rules!$B$16+Rules!$B$17+IF(E34="Uncommon",Rules!$B$19,IF(E34="Rare",Rules!$B$20,Rules!$B$18)))*IF(U34="Y",Rules!$B$21,1),2) -> 11 | Z34: =X34-Y34 -> -0.3 | AA34: =IF(E34="Starter",IF(Z34<0,"Starter (under on purpose)","Starter too strong"),IF(ABS(Z34)<=Rules!$B$24,"Balanced",IF(Z34>0,"Over budget","Under budget"))) -> Balanced
A35: U11 | B35: Reckless Charge | C35: Attack | D35: 0 | E35: Uncommon | F35: Brawler | G35: Deal 8 damage. Lose 2 HP. | H35: Deal 11 damage. Lose 2 HP. | I35: 8 | T35: 2 | X35: =ROUND((I35*Rules!$B$27+J35*Rules!$B$27*Rules!$B$23+K35*Rules!$B$28+L35*Rules!$B$29+M35*Rules!$B$30+N35*Rules!$B$31+(O35*Rules!$B$32+P35*Rules!$B$33+Q35*Rules!$B$34)*IF(R35="Y",Rules!$B$23,1)+S35*Rules!$B$35-T35*Rules!$B$36+V35)*IF(C35="Power",Rules!$B$22,1),2) -> 5 | Y35: =ROUND((D35*Rules!$B$16+Rules!$B$17+IF(E35="Uncommon",Rules!$B$19,IF(E35="Rare",Rules!$B$20,Rules!$B$18)))*IF(U35="Y",Rules!$B$21,1),2) -> 5 | Z35: =X35-Y35 -> 0 | AA35: =IF(E35="Starter",IF(Z35<0,"Starter (under on purpose)","Starter too strong"),IF(ABS(Z35)<=Rules!$B$24,"Balanced",IF(Z35>0,"Over budget","Under budget"))) -> Balanced
A36: U12 | B36: Quick Thinking | C36: Skill | D36: 1 | E36: Uncommon | F36: Tactician | G36: Draw 3 cards, then discard 1. | H36: Draw 4 cards, then discard 1. | M36: 3 | V36: -1 | W36: Other: discard cost; needs choose-a-card UI (Role 3) | X36: =ROUND((I36*Rules!$B$27+J36*Rules!$B$27*Rules!$B$23+K36*Rules!$B$28+L36*Rules!$B$29+M36*Rules!$B$30+N36*Rules!$B$31+(O36*Rules!$B$32+P36*Rules!$B$33+Q36*Rules!$B$34)*IF(R36="Y",Rules!$B$23,1)+S36*Rules!$B$35-T36*Rules!$B$36+V36)*IF(C36="Power",Rules!$B$22,1),2) -> 11 | Y36: =ROUND((D36*Rules!$B$16+Rules!$B$17+IF(E36="Uncommon",Rules!$B$19,IF(E36="Rare",Rules!$B$20,Rules!$B$18)))*IF(U36="Y",Rules!$B$21,1),2) -> 11 | Z36: =X36-Y36 -> 0 | AA36: =IF(E36="Starter",IF(Z36<0,"Starter (under on purpose)","Starter too strong"),IF(ABS(Z36)<=Rules!$B$24,"Balanced",IF(Z36>0,"Over budget","Under budget"))) -> Balanced
A37: U13 | B37: Bulwark | C37: Skill | D37: 2 | E37: Uncommon | F37: Guardian | G37: Gain 10 block. Next turn, gain 5 block. | H37: Gain 13 block. Next turn, gain 7 block. | K37: 15 | W37: Block column = 10 now + 5 next turn | X37: =ROUND((I37*Rules!$B$27+J37*Rules!$B$27*Rules!$B$23+K37*Rules!$B$28+L37*Rules!$B$29+M37*Rules!$B$30+N37*Rules!$B$31+(O37*Rules!$B$32+P37*Rules!$B$33+Q37*Rules!$B$34)*IF(R37="Y",Rules!$B$23,1)+S37*Rules!$B$35-T37*Rules!$B$36+V37)*IF(C37="Power",Rules!$B$22,1),2) -> 18 | Y37: =ROUND((D37*Rules!$B$16+Rules!$B$17+IF(E37="Uncommon",Rules!$B$19,IF(E37="Rare",Rules!$B$20,Rules!$B$18)))*IF(U37="Y",Rules!$B$21,1),2) -> 17 | Z37: =X37-Y37 -> 1 | AA37: =IF(E37="Starter",IF(Z37<0,"Starter (under on purpose)","Starter too strong"),IF(ABS(Z37)<=Rules!$B$24,"Balanced",IF(Z37>0,"Over budget","Under budget"))) -> Balanced
A38: U14 | B38: Catalyst | C38: Skill | D38: 1 | E38: Uncommon | F38: Venom | G38: Double an enemy's Poison. Exhaust. | H38: Triple an enemy's Poison. Exhaust. | U38: Y | V38: 14 | W38: PLAYTEST: scales with existing Poison | X38: =ROUND((I38*Rules!$B$27+J38*Rules!$B$27*Rules!$B$23+K38*Rules!$B$28+L38*Rules!$B$29+M38*Rules!$B$30+N38*Rules!$B$31+(O38*Rules!$B$32+P38*Rules!$B$33+Q38*Rules!$B$34)*IF(R38="Y",Rules!$B$23,1)+S38*Rules!$B$35-T38*Rules!$B$36+V38)*IF(C38="Power",Rules!$B$22,1),2) -> 14 | Y38: =ROUND((D38*Rules!$B$16+Rules!$B$17+IF(E38="Uncommon",Rules!$B$19,IF(E38="Rare",Rules!$B$20,Rules!$B$18)))*IF(U38="Y",Rules!$B$21,1),2) -> 14.3 | Z38: =X38-Y38 -> -0.3 | AA38: =IF(E38="Starter",IF(Z38<0,"Starter (under on purpose)","Starter too strong"),IF(ABS(Z38)<=Rules!$B$24,"Balanced",IF(Z38>0,"Over budget","Under budget"))) -> Balanced
A39: R01 | B39: Thorn Armor | C39: Power | D39: 2 | E39: Rare | F39: Guardian | G39: Whenever you gain block, deal 3 damage to a random enemy. | H39: Whenever you gain block, deal 5 damage to a random enemy. | V39: 9.5 | W39: PLAYTEST: ~2 block cards per turn | X39: =ROUND((I39*Rules!$B$27+J39*Rules!$B$27*Rules!$B$23+K39*Rules!$B$28+L39*Rules!$B$29+M39*Rules!$B$30+N39*Rules!$B$31+(O39*Rules!$B$32+P39*Rules!$B$33+Q39*Rules!$B$34)*IF(R39="Y",Rules!$B$23,1)+S39*Rules!$B$35-T39*Rules!$B$36+V39)*IF(C39="Power",Rules!$B$22,1),2) -> 19 | Y39: =ROUND((D39*Rules!$B$16+Rules!$B$17+IF(E39="Uncommon",Rules!$B$19,IF(E39="Rare",Rules!$B$20,Rules!$B$18)))*IF(U39="Y",Rules!$B$21,1),2) -> 19 | Z39: =X39-Y39 -> 0 | AA39: =IF(E39="Starter",IF(Z39<0,"Starter (under on purpose)","Starter too strong"),IF(ABS(Z39)<=Rules!$B$24,"Balanced",IF(Z39>0,"Over budget","Under budget"))) -> Balanced
A40: R02 | B40: Adrenaline | C40: Skill | D40: 1 | E40: Rare | F40: Tactician | G40: Gain 2 energy. Draw 1 card. Exhaust. | H40: Gain 2 energy. Draw 2 cards. Exhaust. | M40: 1 | N40: 2 | U40: Y | X40: =ROUND((I40*Rules!$B$27+J40*Rules!$B$27*Rules!$B$23+K40*Rules!$B$28+L40*Rules!$B$29+M40*Rules!$B$30+N40*Rules!$B$31+(O40*Rules!$B$32+P40*Rules!$B$33+Q40*Rules!$B$34)*IF(R40="Y",Rules!$B$23,1)+S40*Rules!$B$35-T40*Rules!$B$36+V40)*IF(C40="Power",Rules!$B$22,1),2) -> 16 | Y40: =ROUND((D40*Rules!$B$16+Rules!$B$17+IF(E40="Uncommon",Rules!$B$19,IF(E40="Rare",Rules!$B$20,Rules!$B$18)))*IF(U40="Y",Rules!$B$21,1),2) -> 16.9 | Z40: =X40-Y40 -> -0.9 | AA40: =IF(E40="Starter",IF(Z40<0,"Starter (under on purpose)","Starter too strong"),IF(ABS(Z40)<=Rules!$B$24,"Balanced",IF(Z40>0,"Over budget","Under budget"))) -> Balanced
...

Sheet Summary
A1: Set Summary
A3: Archetype | B3: Starter | C3: Common | D3: Uncommon | E3: Rare | F3: Total
A4: Neutral | B4: =COUNTIFS(Cards!$F$2:$F$300,$A4,Cards!$E$2:$E$300,B$3) -> 3 | C4: =COUNTIFS(Cards!$F$2:$F$300,$A4,Cards!$E$2:$E$300,C$3) -> 3 | D4: =COUNTIFS(Cards!$F$2:$F$300,$A4,Cards!$E$2:$E$300,D$3) -> 0 | E4: =COUNTIFS(Cards!$F$2:$F$300,$A4,Cards!$E$2:$E$300,E$3) -> 1 | F4: =SUM(B4:E4) -> 7
A5: Brawler | B5: =COUNTIFS(Cards!$F$2:$F$300,$A5,Cards!$E$2:$E$300,B$3) -> 0 | C5: =COUNTIFS(Cards!$F$2:$F$300,$A5,Cards!$E$2:$E$300,C$3) -> 4 | D5: =COUNTIFS(Cards!$F$2:$F$300,$A5,Cards!$E$2:$E$300,D$3) -> 4 | E5: =COUNTIFS(Cards!$F$2:$F$300,$A5,Cards!$E$2:$E$300,E$3) -> 2 | F5: =SUM(B5:E5) -> 10
A6: Guardian | B6: =COUNTIFS(Cards!$F$2:$F$300,$A6,Cards!$E$2:$E$300,B$3) -> 0 | C6: =COUNTIFS(Cards!$F$2:$F$300,$A6,Cards!$E$2:$E$300,C$3) -> 5 | D6: =COUNTIFS(Cards!$F$2:$F$300,$A6,Cards!$E$2:$E$300,D$3) -> 4 | E6: =COUNTIFS(Cards!$F$2:$F$300,$A6,Cards!$E$2:$E$300,E$3) -> 1 | F6: =SUM(B6:E6) -> 10
A7: Venom | B7: =COUNTIFS(Cards!$F$2:$F$300,$A7,Cards!$E$2:$E$300,B$3) -> 0 | C7: =COUNTIFS(Cards!$F$2:$F$300,$A7,Cards!$E$2:$E$300,C$3) -> 3 | D7: =COUNTIFS(Cards!$F$2:$F$300,$A7,Cards!$E$2:$E$300,D$3) -> 3 | E7: =COUNTIFS(Cards!$F$2:$F$300,$A7,Cards!$E$2:$E$300,E$3) -> 1 | F7: =SUM(B7:E7) -> 7
A8: Tactician | B8: =COUNTIFS(Cards!$F$2:$F$300,$A8,Cards!$E$2:$E$300,B$3) -> 0 | C8: =COUNTIFS(Cards!$F$2:$F$300,$A8,Cards!$E$2:$E$300,C$3) -> 5 | D8: =COUNTIFS(Cards!$F$2:$F$300,$A8,Cards!$E$2:$E$300,D$3) -> 3 | E8: =COUNTIFS(Cards!$F$2:$F$300,$A8,Cards!$E$2:$E$300,E$3) -> 1 | F8: =SUM(B8:E8) -> 9
A9: Total | B9: =SUM(B4:B8) -> 3 | C9: =SUM(C4:C8) -> 20 | D9: =SUM(D4:D8) -> 14 | E9: =SUM(E4:E8) -> 6 | F9: =SUM(F4:F8) -> 43
A11: Balance status
A12: Balanced | B12: =COUNTIF(Cards!$AA$2:$AA$300,A12) -> 40
A13: Over budget | B13: =COUNTIF(Cards!$AA$2:$AA$300,A13) -> 0
A14: Under budget | B14: =COUNTIF(Cards!$AA$2:$AA$300,A14) -> 0
A15: Starter (under on purpose) | B15: =COUNTIF(Cards!$AA$2:$AA$300,A15) -> 3
A17: Type
A18: Attack | B18: =COUNTIFS(Cards!$C$2:$C$300,A18,Cards!$E$2:$E$300,"<>Starter") -> 15
A19: Skill | B19: =COUNTIFS(Cards!$C$2:$C$300,A19,Cards!$E$2:$E$300,"<>Starter") -> 20
A20: Power | B20: =COUNTIFS(Cards!$C$2:$C$300,A20,Cards!$E$2:$E$300,"<>Starter") -> 5
A22: Starter deck
A23: Strike | B23: 5
A24: Defend | B24: 4
A25: Lantern Bash | B25: 1
A26: Total | B26: =SUM(B23:B25) -> 10
A28: Reward odds per card offered
A29: Common | B29: 0.6
A30: Uncommon | B30: 0.33
A31: Rare | B31: 0.07

Sheet Keywords
A1: Keywords (show as tap-to-explain on cards)
A3: Keyword | B3: Rule | C3: Who implements
A4: Block | B4: Prevents damage. All block is removed at the start of your next turn. | C4: Role 1
A5: Heal | B5: Restore HP, up to max HP. | C5: Role 1
A6: Poison | B6: At the start of the poisoned creature's turn, it loses HP equal to its Poison, then Poison goes down by 1. | C6: Role 1
A7: Weak | B7: Deals 25% less attack damage. Lasts the listed number of turns. | C7: Role 1
A8: Vulnerable | B8: Takes 50% more attack damage. Lasts the listed number of turns. | C8: Role 1
A9: Strength | B9: Each attack hit deals +1 damage per Strength. Lasts the whole fight. | C9: Role 1
A10: Exhaust | B10: After playing, remove this card from your deck for the rest of the fight (it returns next fight). | C10: Role 2
A11: Power | B11: Stays in play for the rest of the fight instead of going to the discard pile. | C11: Role 2
A12: ALL enemies | B12: Hits every enemy in the fight. | C12: Role 1
A13: Intent | B13: Enemies show what they'll do next turn. Some cards (Parry) check it. | C13: Role 1 + Role 3
A14: Discard | B14: Choose a card from your hand to put in the discard pile. | C14: Role 2 + Role 3
