Workbook

Sheet How to use
A1: How to use this workbook (Alpha set: 128 cards)
A3: Cards tab: one row per card. Fill in the blue effect columns (I–W); Value, Budget, Difference and Status calculate automatically.
A4: • Budget = (Cost × points per energy + base value + rarity bonus), × exhaust multiplier if the card exhausts.
A5: • Value = sum of each effect × its price (Rules tab), + Retain value if the card Retains. Power cards list their per-turn effect and are multiplied by the power multiplier.
A6: • 'Other value' is for unique effects the price list can't capture. Cards marked PLAYTEST in Notes rely on it, so balance those by playing.
A7: • Status: Balanced (within tolerance), Over budget, Under budget. Starter cards stay under budget so every reward feels like an upgrade.
A8: • Legendary rows are shaded. Legendaries are Unique (one copy per deck).
A9: • To add a card: type it into the first empty row below the set. Formulas are already there.
A11: Rules tab: combat numbers, budget formula and effect prices. Summary: counts by archetype and rarity, balance status, reward odds.
A12: Keywords: rules text for every keyword. New Mechanics: what needs new code before these cards work in the game.
A14: Cards C01–C20, U01–U14, R01–R06 and the starters are unchanged from v1 (already in the game). Everything else is new in the alpha set.
A16: Example row: C01 Slash — Attack, cost 1, Common, Damage 9 → Value 9, Budget 9, Balanced.

Sheet Rules
A1: Dungeon Roguelike – Balance Rules (Alpha set, 128 cards)
A2: Blue cells on yellow are inputs: change them and every card's value/budget on the Cards tab recalculates.
A4: Baseline (combat)
A5: Player max HP | B5: 70 | C5: Starting value; tune in playtests
A6: Energy per turn | B6: 3
A7: Cards drawn per turn | B7: 5
A8: Starter deck size | B8: 10 | C8: 5 Strike, 4 Defend, 1 Lantern Bash
A9: Normal enemy HP (min) | B9: 12 | C9: Simulation: fights last ~2 turns at 12-25 HP; ~35-45 would hit the 3-4 turn target
A10: Normal enemy HP (max) | B10: 25
A11: Elite HP (min) | B11: 40
A12: Elite HP (max) | B12: 60
A13: Boss HP | B13: 130 | C13: Single boss for v1
A15: Budget formula
A16: Points per energy | B16: 6 | C16: Budget = cost × this + base + rarity bonus
A17: Base card value | B17: 3 | C17: Being a card is worth something (draw + hand slot)
A18: Rarity bonus: Common | B18: 0
A19: Rarity bonus: Uncommon | B19: 2
A20: Rarity bonus: Rare | B20: 4
A21: Rarity bonus: Legendary | B21: 6 | C21: NEW. Legendaries are also Unique: one copy per deck
A22: Exhaust budget multiplier | B22: 1.3 | C22: One-use cards get 30% more budget
A23: Power value multiplier | B23: 2 | C23: Power effects listed per turn are worth ×2
A24: 'All enemies' multiplier | B24: 1.5 | C24: Applies to AoE damage and debuffs that hit all enemies
A25: Balanced tolerance (±) | B25: 1.5 | C25: Value within this of budget = Balanced
A27: Effect price list (points per 1)
A28: Damage | B28: 1
A29: Block | B29: 1.2 | C29: Reliable defense is slightly better than damage
A30: Heal | B30: 1.5 | C30: Healing is scarce in roguelikes; keep it pricey
A31: Draw | B31: 4
A32: Energy | B32: 6 | C32: Also used for 'next turn, gain energy'
A33: Weak (per turn) | B33: 3 | C33: Enemy deals 25% less damage
A34: Vulnerable (per turn) | B34: 3 | C34: Enemy takes 50% more damage
A35: Poison (per stack) | B35: 1.5
A36: Strength (per stack) | B36: 4 | C36: +1 damage per attack hit for the rest of the fight
A37: HP loss (per 1) | B37: 1.5 | C37: A cost to the player; subtracts value
A38: Retain | B38: 2 | C38: NEW. Flat value for a card that stays in your hand

Sheet Cards
A1: ID | B1: Name | C1: Type | D1: Cost | E1: Rarity | F1: Archetype | G1: Card text | H1: Upgraded text | I1: Damage | J1: AoE dmg | K1: Block | L1: Heal | M1: Draw | N1: Energy | O1: Weak | P1: Vuln | Q1: Poison | R1: Debuffs hit all? | S1: Strength | T1: HP loss | U1: Exhaust? | V1: Retain? | W1: Other value | X1: Notes | Y1: Value | Z1: Budget | AA1: Difference | AB1: Status
A2: S01 | B2: Strike | C2: Attack | D2: 1 | E2: Starter | F2: Neutral | G2: Deal 6 damage. | H2: Deal 9 damage. | I2: 6 | X2: x5 in starter deck | Y2: =ROUND((I2*Rules!$B$28+J2*Rules!$B$28*Rules!$B$24+K2*Rules!$B$29+L2*Rules!$B$30+M2*Rules!$B$31+N2*Rules!$B$32+(O2*Rules!$B$33+P2*Rules!$B$34+Q2*Rules!$B$35)*IF(R2="Y",Rules!$B$24,1)+S2*Rules!$B$36-T2*Rules!$B$37+IF(V2="Y",Rules!$B$38,0)+W2)*IF(C2="Power",Rules!$B$23,1),2) -> 6 | Z2: =ROUND((D2*Rules!$B$16+Rules!$B$17+IF(E2="Legendary",Rules!$B$21,IF(E2="Rare",Rules!$B$20,IF(E2="Uncommon",Rules!$B$19,Rules!$B$18))))*IF(U2="Y",Rules!$B$22,1),2) -> 9 | AA2: =Y2-Z2 -> -3 | AB2: =IF(E2="Starter",IF(AA2<0,"Starter (under on purpose)","Starter too strong"),IF(ABS(AA2)<=Rules!$B$25,"Balanced",IF(AA2>0,"Over budget","Under budget"))) -> Starter (under on purpose)
A3: S02 | B3: Defend | C3: Skill | D3: 1 | E3: Starter | F3: Neutral | G3: Gain 5 block. | H3: Gain 8 block. | K3: 5 | X3: x4 in starter deck | Y3: =ROUND((I3*Rules!$B$28+J3*Rules!$B$28*Rules!$B$24+K3*Rules!$B$29+L3*Rules!$B$30+M3*Rules!$B$31+N3*Rules!$B$32+(O3*Rules!$B$33+P3*Rules!$B$34+Q3*Rules!$B$35)*IF(R3="Y",Rules!$B$24,1)+S3*Rules!$B$36-T3*Rules!$B$37+IF(V3="Y",Rules!$B$38,0)+W3)*IF(C3="Power",Rules!$B$23,1),2) -> 6 | Z3: =ROUND((D3*Rules!$B$16+Rules!$B$17+IF(E3="Legendary",Rules!$B$21,IF(E3="Rare",Rules!$B$20,IF(E3="Uncommon",Rules!$B$19,Rules!$B$18))))*IF(U3="Y",Rules!$B$22,1),2) -> 9 | AA3: =Y3-Z3 -> -3 | AB3: =IF(E3="Starter",IF(AA3<0,"Starter (under on purpose)","Starter too strong"),IF(ABS(AA3)<=Rules!$B$25,"Balanced",IF(AA3>0,"Over budget","Under budget"))) -> Starter (under on purpose)
A4: S03 | B4: Lantern Bash | C4: Attack | D4: 1 | E4: Starter | F4: Neutral | G4: Deal 5 damage. Apply 1 Vulnerable. | H4: Deal 7 damage. Apply 2 Vulnerable. | I4: 5 | P4: 1 | X4: x1 signature card; teaches debuffs | Y4: =ROUND((I4*Rules!$B$28+J4*Rules!$B$28*Rules!$B$24+K4*Rules!$B$29+L4*Rules!$B$30+M4*Rules!$B$31+N4*Rules!$B$32+(O4*Rules!$B$33+P4*Rules!$B$34+Q4*Rules!$B$35)*IF(R4="Y",Rules!$B$24,1)+S4*Rules!$B$36-T4*Rules!$B$37+IF(V4="Y",Rules!$B$38,0)+W4)*IF(C4="Power",Rules!$B$23,1),2) -> 8 | Z4: =ROUND((D4*Rules!$B$16+Rules!$B$17+IF(E4="Legendary",Rules!$B$21,IF(E4="Rare",Rules!$B$20,IF(E4="Uncommon",Rules!$B$19,Rules!$B$18))))*IF(U4="Y",Rules!$B$22,1),2) -> 9 | AA4: =Y4-Z4 -> -1 | AB4: =IF(E4="Starter",IF(AA4<0,"Starter (under on purpose)","Starter too strong"),IF(ABS(AA4)<=Rules!$B$25,"Balanced",IF(AA4>0,"Over budget","Under budget"))) -> Starter (under on purpose)
A5: C01 | B5: Slash | C5: Attack | D5: 1 | E5: Common | F5: Neutral | G5: Deal 9 damage. | H5: Deal 12 damage. | I5: 9 | Y5: =ROUND((I5*Rules!$B$28+J5*Rules!$B$28*Rules!$B$24+K5*Rules!$B$29+L5*Rules!$B$30+M5*Rules!$B$31+N5*Rules!$B$32+(O5*Rules!$B$33+P5*Rules!$B$34+Q5*Rules!$B$35)*IF(R5="Y",Rules!$B$24,1)+S5*Rules!$B$36-T5*Rules!$B$37+IF(V5="Y",Rules!$B$38,0)+W5)*IF(C5="Power",Rules!$B$23,1),2) -> 9 | Z5: =ROUND((D5*Rules!$B$16+Rules!$B$17+IF(E5="Legendary",Rules!$B$21,IF(E5="Rare",Rules!$B$20,IF(E5="Uncommon",Rules!$B$19,Rules!$B$18))))*IF(U5="Y",Rules!$B$22,1),2) -> 9 | AA5: =Y5-Z5 -> 0 | AB5: =IF(E5="Starter",IF(AA5<0,"Starter (under on purpose)","Starter too strong"),IF(ABS(AA5)<=Rules!$B$25,"Balanced",IF(AA5>0,"Over budget","Under budget"))) -> Balanced
A6: C02 | B6: Quick Jab | C6: Attack | D6: 0 | E6: Common | F6: Brawler | G6: Deal 3 damage. | H6: Deal 5 damage. | I6: 3 | X6: Free attacks scale with Strength | Y6: =ROUND((I6*Rules!$B$28+J6*Rules!$B$28*Rules!$B$24+K6*Rules!$B$29+L6*Rules!$B$30+M6*Rules!$B$31+N6*Rules!$B$32+(O6*Rules!$B$33+P6*Rules!$B$34+Q6*Rules!$B$35)*IF(R6="Y",Rules!$B$24,1)+S6*Rules!$B$36-T6*Rules!$B$37+IF(V6="Y",Rules!$B$38,0)+W6)*IF(C6="Power",Rules!$B$23,1),2) -> 3 | Z6: =ROUND((D6*Rules!$B$16+Rules!$B$17+IF(E6="Legendary",Rules!$B$21,IF(E6="Rare",Rules!$B$20,IF(E6="Uncommon",Rules!$B$19,Rules!$B$18))))*IF(U6="Y",Rules!$B$22,1),2) -> 3 | AA6: =Y6-Z6 -> 0 | AB6: =IF(E6="Starter",IF(AA6<0,"Starter (under on purpose)","Starter too strong"),IF(ABS(AA6)<=Rules!$B$25,"Balanced",IF(AA6>0,"Over budget","Under budget"))) -> Balanced
A7: C03 | B7: Cleave | C7: Attack | D7: 1 | E7: Common | F7: Neutral | G7: Deal 6 damage to ALL enemies. | H7: Deal 9 damage to ALL enemies. | J7: 6 | Y7: =ROUND((I7*Rules!$B$28+J7*Rules!$B$28*Rules!$B$24+K7*Rules!$B$29+L7*Rules!$B$30+M7*Rules!$B$31+N7*Rules!$B$32+(O7*Rules!$B$33+P7*Rules!$B$34+Q7*Rules!$B$35)*IF(R7="Y",Rules!$B$24,1)+S7*Rules!$B$36-T7*Rules!$B$37+IF(V7="Y",Rules!$B$38,0)+W7)*IF(C7="Power",Rules!$B$23,1),2) -> 9 | Z7: =ROUND((D7*Rules!$B$16+Rules!$B$17+IF(E7="Legendary",Rules!$B$21,IF(E7="Rare",Rules!$B$20,IF(E7="Uncommon",Rules!$B$19,Rules!$B$18))))*IF(U7="Y",Rules!$B$22,1),2) -> 9 | AA7: =Y7-Z7 -> 0 | AB7: =IF(E7="Starter",IF(AA7<0,"Starter (under on purpose)","Starter too strong"),IF(ABS(AA7)<=Rules!$B$25,"Balanced",IF(AA7>0,"Over budget","Under budget"))) -> Balanced
A8: C04 | B8: Heavy Swing | C8: Attack | D8: 2 | E8: Common | F8: Brawler | G8: Deal 15 damage. | H8: Deal 20 damage. | I8: 15 | Y8: =ROUND((I8*Rules!$B$28+J8*Rules!$B$28*Rules!$B$24+K8*Rules!$B$29+L8*Rules!$B$30+M8*Rules!$B$31+N8*Rules!$B$32+(O8*Rules!$B$33+P8*Rules!$B$34+Q8*Rules!$B$35)*IF(R8="Y",Rules!$B$24,1)+S8*Rules!$B$36-T8*Rules!$B$37+IF(V8="Y",Rules!$B$38,0)+W8)*IF(C8="Power",Rules!$B$23,1),2) -> 15 | Z8: =ROUND((D8*Rules!$B$16+Rules!$B$17+IF(E8="Legendary",Rules!$B$21,IF(E8="Rare",Rules!$B$20,IF(E8="Uncommon",Rules!$B$19,Rules!$B$18))))*IF(U8="Y",Rules!$B$22,1),2) -> 15 | AA8: =Y8-Z8 -> 0 | AB8: =IF(E8="Starter",IF(AA8<0,"Starter (under on purpose)","Starter too strong"),IF(ABS(AA8)<=Rules!$B$25,"Balanced",IF(AA8>0,"Over budget","Under budget"))) -> Balanced
A9: C05 | B9: Twin Strike | C9: Attack | D9: 1 | E9: Common | F9: Brawler | G9: Deal 4 damage twice. | H9: Deal 5 damage twice. | I9: 8 | W9: 1 | X9: Other: multi-hit doubles Strength bonus | Y9: =ROUND((I9*Rules!$B$28+J9*Rules!$B$28*Rules!$B$24+K9*Rules!$B$29+L9*Rules!$B$30+M9*Rules!$B$31+N9*Rules!$B$32+(O9*Rules!$B$33+P9*Rules!$B$34+Q9*Rules!$B$35)*IF(R9="Y",Rules!$B$24,1)+S9*Rules!$B$36-T9*Rules!$B$37+IF(V9="Y",Rules!$B$38,0)+W9)*IF(C9="Power",Rules!$B$23,1),2) -> 9 | Z9: =ROUND((D9*Rules!$B$16+Rules!$B$17+IF(E9="Legendary",Rules!$B$21,IF(E9="Rare",Rules!$B$20,IF(E9="Uncommon",Rules!$B$19,Rules!$B$18))))*IF(U9="Y",Rules!$B$22,1),2) -> 9 | AA9: =Y9-Z9 -> 0 | AB9: =IF(E9="Starter",IF(AA9<0,"Starter (under on purpose)","Starter too strong"),IF(ABS(AA9)<=Rules!$B$25,"Balanced",IF(AA9>0,"Over budget","Under budget"))) -> Balanced
A10: C06 | B10: Poisoned Blade | C10: Attack | D10: 1 | E10: Common | F10: Venom | G10: Deal 3 damage. Apply 4 Poison. | H10: Deal 4 damage. Apply 6 Poison. | I10: 3 | Q10: 4 | Y10: =ROUND((I10*Rules!$B$28+J10*Rules!$B$28*Rules!$B$24+K10*Rules!$B$29+L10*Rules!$B$30+M10*Rules!$B$31+N10*Rules!$B$32+(O10*Rules!$B$33+P10*Rules!$B$34+Q10*Rules!$B$35)*IF(R10="Y",Rules!$B$24,1)+S10*Rules!$B$36-T10*Rules!$B$37+IF(V10="Y",Rules!$B$38,0)+W10)*IF(C10="Power",Rules!$B$23,1),2) -> 9 | Z10: =ROUND((D10*Rules!$B$16+Rules!$B$17+IF(E10="Legendary",Rules!$B$21,IF(E10="Rare",Rules!$B$20,IF(E10="Uncommon",Rules!$B$19,Rules!$B$18))))*IF(U10="Y",Rules!$B$22,1),2) -> 9 | AA10: =Y10-Z10 -> 0 | AB10: =IF(E10="Starter",IF(AA10<0,"Starter (under on purpose)","Starter too strong"),IF(ABS(AA10)<=Rules!$B$25,"Balanced",IF(AA10>0,"Over budget","Under budget"))) -> Balanced
A11: C07 | B11: Shield Slam | C11: Attack | D11: 1 | E11: Common | F11: Guardian | G11: Deal 4 damage. Gain 4 block. | H11: Deal 6 damage. Gain 6 block. | I11: 4 | K11: 4 | Y11: =ROUND((I11*Rules!$B$28+J11*Rules!$B$28*Rules!$B$24+K11*Rules!$B$29+L11*Rules!$B$30+M11*Rules!$B$31+N11*Rules!$B$32+(O11*Rules!$B$33+P11*Rules!$B$34+Q11*Rules!$B$35)*IF(R11="Y",Rules!$B$24,1)+S11*Rules!$B$36-T11*Rules!$B$37+IF(V11="Y",Rules!$B$38,0)+W11)*IF(C11="Power",Rules!$B$23,1),2) -> 8.8 | Z11: =ROUND((D11*Rules!$B$16+Rules!$B$17+IF(E11="Legendary",Rules!$B$21,IF(E11="Rare",Rules!$B$20,IF(E11="Uncommon",Rules!$B$19,Rules!$B$18))))*IF(U11="Y",Rules!$B$22,1),2) -> 9 | AA11: =Y11-Z11 -> -0.2 | AB11: =IF(E11="Starter",IF(AA11<0,"Starter (under on purpose)","Starter too strong"),IF(ABS(AA11)<=Rules!$B$25,"Balanced",IF(AA11>0,"Over budget","Under budget"))) -> Balanced
A12: C08 | B12: Venom Fang | C12: Skill | D12: 0 | E12: Common | F12: Venom | G12: Apply 2 Poison. | H12: Apply 3 Poison. | Q12: 2 | Y12: =ROUND((I12*Rules!$B$28+J12*Rules!$B$28*Rules!$B$24+K12*Rules!$B$29+L12*Rules!$B$30+M12*Rules!$B$31+N12*Rules!$B$32+(O12*Rules!$B$33+P12*Rules!$B$34+Q12*Rules!$B$35)*IF(R12="Y",Rules!$B$24,1)+S12*Rules!$B$36-T12*Rules!$B$37+IF(V12="Y",Rules!$B$38,0)+W12)*IF(C12="Power",Rules!$B$23,1),2) -> 3 | Z12: =ROUND((D12*Rules!$B$16+Rules!$B$17+IF(E12="Legendary",Rules!$B$21,IF(E12="Rare",Rules!$B$20,IF(E12="Uncommon",Rules!$B$19,Rules!$B$18))))*IF(U12="Y",Rules!$B$22,1),2) -> 3 | AA12: =Y12-Z12 -> 0 | AB12: =IF(E12="Starter",IF(AA12<0,"Starter (under on purpose)","Starter too strong"),IF(ABS(AA12)<=Rules!$B$25,"Balanced",IF(AA12>0,"Over budget","Under budget"))) -> Balanced
A13: C09 | B13: Pommel Strike | C13: Attack | D13: 1 | E13: Common | F13: Tactician | G13: Deal 5 damage. Draw 1 card. | H13: Deal 7 damage. Draw 1 card. | I13: 5 | M13: 1 | Y13: =ROUND((I13*Rules!$B$28+J13*Rules!$B$28*Rules!$B$24+K13*Rules!$B$29+L13*Rules!$B$30+M13*Rules!$B$31+N13*Rules!$B$32+(O13*Rules!$B$33+P13*Rules!$B$34+Q13*Rules!$B$35)*IF(R13="Y",Rules!$B$24,1)+S13*Rules!$B$36-T13*Rules!$B$37+IF(V13="Y",Rules!$B$38,0)+W13)*IF(C13="Power",Rules!$B$23,1),2) -> 9 | Z13: =ROUND((D13*Rules!$B$16+Rules!$B$17+IF(E13="Legendary",Rules!$B$21,IF(E13="Rare",Rules!$B$20,IF(E13="Uncommon",Rules!$B$19,Rules!$B$18))))*IF(U13="Y",Rules!$B$22,1),2) -> 9 | AA13: =Y13-Z13 -> 0 | AB13: =IF(E13="Starter",IF(AA13<0,"Starter (under on purpose)","Starter too strong"),IF(ABS(AA13)<=Rules!$B$25,"Balanced",IF(AA13>0,"Over budget","Under budget"))) -> Balanced
A14: C10 | B14: Torch Swing | C14: Attack | D14: 1 | E14: Common | F14: Tactician | G14: Deal 6 damage. Apply 1 Vulnerable. | H14: Deal 8 damage. Apply 2 Vulnerable. | I14: 6 | P14: 1 | Y14: =ROUND((I14*Rules!$B$28+J14*Rules!$B$28*Rules!$B$24+K14*Rules!$B$29+L14*Rules!$B$30+M14*Rules!$B$31+N14*Rules!$B$32+(O14*Rules!$B$33+P14*Rules!$B$34+Q14*Rules!$B$35)*IF(R14="Y",Rules!$B$24,1)+S14*Rules!$B$36-T14*Rules!$B$37+IF(V14="Y",Rules!$B$38,0)+W14)*IF(C14="Power",Rules!$B$23,1),2) -> 9 | Z14: =ROUND((D14*Rules!$B$16+Rules!$B$17+IF(E14="Legendary",Rules!$B$21,IF(E14="Rare",Rules!$B$20,IF(E14="Uncommon",Rules!$B$19,Rules!$B$18))))*IF(U14="Y",Rules!$B$22,1),2) -> 9 | AA14: =Y14-Z14 -> 0 | AB14: =IF(E14="Starter",IF(AA14<0,"Starter (under on purpose)","Starter too strong"),IF(ABS(AA14)<=Rules!$B$25,"Balanced",IF(AA14>0,"Over budget","Under budget"))) -> Balanced
A15: C11 | B15: Brace | C15: Skill | D15: 1 | E15: Common | F15: Guardian | G15: Gain 7 block. | H15: Gain 10 block. | K15: 7 | Y15: =ROUND((I15*Rules!$B$28+J15*Rules!$B$28*Rules!$B$24+K15*Rules!$B$29+L15*Rules!$B$30+M15*Rules!$B$31+N15*Rules!$B$32+(O15*Rules!$B$33+P15*Rules!$B$34+Q15*Rules!$B$35)*IF(R15="Y",Rules!$B$24,1)+S15*Rules!$B$36-T15*Rules!$B$37+IF(V15="Y",Rules!$B$38,0)+W15)*IF(C15="Power",Rules!$B$23,1),2) -> 8.4 | Z15: =ROUND((D15*Rules!$B$16+Rules!$B$17+IF(E15="Legendary",Rules!$B$21,IF(E15="Rare",Rules!$B$20,IF(E15="Uncommon",Rules!$B$19,Rules!$B$18))))*IF(U15="Y",Rules!$B$22,1),2) -> 9 | AA15: =Y15-Z15 -> -0.6 | AB15: =IF(E15="Starter",IF(AA15<0,"Starter (under on purpose)","Starter too strong"),IF(ABS(AA15)<=Rules!$B$25,"Balanced",IF(AA15>0,"Over budget","Under budget"))) -> Balanced
A16: C12 | B16: Raise Shield | C16: Skill | D16: 2 | E16: Common | F16: Guardian | G16: Gain 12 block. | H16: Gain 16 block. | K16: 12 | Y16: =ROUND((I16*Rules!$B$28+J16*Rules!$B$28*Rules!$B$24+K16*Rules!$B$29+L16*Rules!$B$30+M16*Rules!$B$31+N16*Rules!$B$32+(O16*Rules!$B$33+P16*Rules!$B$34+Q16*Rules!$B$35)*IF(R16="Y",Rules!$B$24,1)+S16*Rules!$B$36-T16*Rules!$B$37+IF(V16="Y",Rules!$B$38,0)+W16)*IF(C16="Power",Rules!$B$23,1),2) -> 14.4 | Z16: =ROUND((D16*Rules!$B$16+Rules!$B$17+IF(E16="Legendary",Rules!$B$21,IF(E16="Rare",Rules!$B$20,IF(E16="Uncommon",Rules!$B$19,Rules!$B$18))))*IF(U16="Y",Rules!$B$22,1),2) -> 15 | AA16: =Y16-Z16 -> -0.6 | AB16: =IF(E16="Starter",IF(AA16<0,"Starter (under on purpose)","Starter too strong"),IF(ABS(AA16)<=Rules!$B$25,"Balanced",IF(AA16>0,"Over budget","Under budget"))) -> Balanced
A17: C13 | B17: Dodge Roll | C17: Skill | D17: 1 | E17: Common | F17: Guardian | G17: Gain 4 block. Draw 1 card. | H17: Gain 6 block. Draw 1 card. | K17: 4 | M17: 1 | Y17: =ROUND((I17*Rules!$B$28+J17*Rules!$B$28*Rules!$B$24+K17*Rules!$B$29+L17*Rules!$B$30+M17*Rules!$B$31+N17*Rules!$B$32+(O17*Rules!$B$33+P17*Rules!$B$34+Q17*Rules!$B$35)*IF(R17="Y",Rules!$B$24,1)+S17*Rules!$B$36-T17*Rules!$B$37+IF(V17="Y",Rules!$B$38,0)+W17)*IF(C17="Power",Rules!$B$23,1),2) -> 8.8 | Z17: =ROUND((D17*Rules!$B$16+Rules!$B$17+IF(E17="Legendary",Rules!$B$21,IF(E17="Rare",Rules!$B$20,IF(E17="Uncommon",Rules!$B$19,Rules!$B$18))))*IF(U17="Y",Rules!$B$22,1),2) -> 9 | AA17: =Y17-Z17 -> -0.2 | AB17: =IF(E17="Starter",IF(AA17<0,"Starter (under on purpose)","Starter too strong"),IF(ABS(AA17)<=Rules!$B$25,"Balanced",IF(AA17>0,"Over budget","Under budget"))) -> Balanced
A18: C14 | B18: Toxic Vial | C18: Skill | D18: 1 | E18: Common | F18: Venom | G18: Apply 6 Poison. | H18: Apply 9 Poison. | Q18: 6 | Y18: =ROUND((I18*Rules!$B$28+J18*Rules!$B$28*Rules!$B$24+K18*Rules!$B$29+L18*Rules!$B$30+M18*Rules!$B$31+N18*Rules!$B$32+(O18*Rules!$B$33+P18*Rules!$B$34+Q18*Rules!$B$35)*IF(R18="Y",Rules!$B$24,1)+S18*Rules!$B$36-T18*Rules!$B$37+IF(V18="Y",Rules!$B$38,0)+W18)*IF(C18="Power",Rules!$B$23,1),2) -> 9 | Z18: =ROUND((D18*Rules!$B$16+Rules!$B$17+IF(E18="Legendary",Rules!$B$21,IF(E18="Rare",Rules!$B$20,IF(E18="Uncommon",Rules!$B$19,Rules!$B$18))))*IF(U18="Y",Rules!$B$22,1),2) -> 9 | AA18: =Y18-Z18 -> 0 | AB18: =IF(E18="Starter",IF(AA18<0,"Starter (under on purpose)","Starter too strong"),IF(ABS(AA18)<=Rules!$B$25,"Balanced",IF(AA18>0,"Over budget","Under budget"))) -> Balanced
A19: C15 | B19: Bandage | C19: Skill | D19: 1 | E19: Common | F19: Neutral | G19: Gain 4 block. Heal 4 HP. Exhaust. | H19: Gain 5 block. Heal 6 HP. Exhaust. | K19: 4 | L19: 4 | U19: Y | X19: Only in-combat heal at Common | Y19: =ROUND((I19*Rules!$B$28+J19*Rules!$B$28*Rules!$B$24+K19*Rules!$B$29+L19*Rules!$B$30+M19*Rules!$B$31+N19*Rules!$B$32+(O19*Rules!$B$33+P19*Rules!$B$34+Q19*Rules!$B$35)*IF(R19="Y",Rules!$B$24,1)+S19*Rules!$B$36-T19*Rules!$B$37+IF(V19="Y",Rules!$B$38,0)+W19)*IF(C19="Power",Rules!$B$23,1),2) -> 10.8 | Z19: =ROUND((D19*Rules!$B$16+Rules!$B$17+IF(E19="Legendary",Rules!$B$21,IF(E19="Rare",Rules!$B$20,IF(E19="Uncommon",Rules!$B$19,Rules!$B$18))))*IF(U19="Y",Rules!$B$22,1),2) -> 11.7 | AA19: =Y19-Z19 -> -0.9 | AB19: =IF(E19="Starter",IF(AA19<0,"Starter (under on purpose)","Starter too strong"),IF(ABS(AA19)<=Rules!$B$25,"Balanced",IF(AA19>0,"Over budget","Under budget"))) -> Balanced
A20: C16 | B20: Scout Ahead | C20: Skill | D20: 1 | E20: Common | F20: Tactician | G20: Draw 2 cards. | H20: Draw 3 cards. | M20: 2 | Y20: =ROUND((I20*Rules!$B$28+J20*Rules!$B$28*Rules!$B$24+K20*Rules!$B$29+L20*Rules!$B$30+M20*Rules!$B$31+N20*Rules!$B$32+(O20*Rules!$B$33+P20*Rules!$B$34+Q20*Rules!$B$35)*IF(R20="Y",Rules!$B$24,1)+S20*Rules!$B$36-T20*Rules!$B$37+IF(V20="Y",Rules!$B$38,0)+W20)*IF(C20="Power",Rules!$B$23,1),2) -> 8 | Z20: =ROUND((D20*Rules!$B$16+Rules!$B$17+IF(E20="Legendary",Rules!$B$21,IF(E20="Rare",Rules!$B$20,IF(E20="Uncommon",Rules!$B$19,Rules!$B$18))))*IF(U20="Y",Rules!$B$22,1),2) -> 9 | AA20: =Y20-Z20 -> -1 | AB20: =IF(E20="Starter",IF(AA20<0,"Starter (under on purpose)","Starter too strong"),IF(ABS(AA20)<=Rules!$B$25,"Balanced",IF(AA20>0,"Over budget","Under budget"))) -> Balanced
A21: C17 | B21: Smoke Bomb | C21: Skill | D21: 1 | E21: Common | F21: Tactician | G21: Apply 2 Weak to ALL enemies. | H21: Apply 3 Weak to ALL enemies. | O21: 2 | R21: Y | Y21: =ROUND((I21*Rules!$B$28+J21*Rules!$B$28*Rules!$B$24+K21*Rules!$B$29+L21*Rules!$B$30+M21*Rules!$B$31+N21*Rules!$B$32+(O21*Rules!$B$33+P21*Rules!$B$34+Q21*Rules!$B$35)*IF(R21="Y",Rules!$B$24,1)+S21*Rules!$B$36-T21*Rules!$B$37+IF(V21="Y",Rules!$B$38,0)+W21)*IF(C21="Power",Rules!$B$23,1),2) -> 9 | Z21: =ROUND((D21*Rules!$B$16+Rules!$B$17+IF(E21="Legendary",Rules!$B$21,IF(E21="Rare",Rules!$B$20,IF(E21="Uncommon",Rules!$B$19,Rules!$B$18))))*IF(U21="Y",Rules!$B$22,1),2) -> 9 | AA21: =Y21-Z21 -> 0 | AB21: =IF(E21="Starter",IF(AA21<0,"Starter (under on purpose)","Starter too strong"),IF(ABS(AA21)<=Rules!$B$25,"Balanced",IF(AA21>0,"Over budget","Under budget"))) -> Balanced
A22: C18 | B22: Sharpen | C22: Skill | D22: 0 | E22: Common | F22: Brawler | G22: Your next Attack this turn deals 3 extra damage. | H22: Your next Attack this turn deals 5 extra damage. | W22: 3 | X22: Other: conditional +3 damage | Y22: =ROUND((I22*Rules!$B$28+J22*Rules!$B$28*Rules!$B$24+K22*Rules!$B$29+L22*Rules!$B$30+M22*Rules!$B$31+N22*Rules!$B$32+(O22*Rules!$B$33+P22*Rules!$B$34+Q22*Rules!$B$35)*IF(R22="Y",Rules!$B$24,1)+S22*Rules!$B$36-T22*Rules!$B$37+IF(V22="Y",Rules!$B$38,0)+W22)*IF(C22="Power",Rules!$B$23,1),2) -> 3 | Z22: =ROUND((D22*Rules!$B$16+Rules!$B$17+IF(E22="Legendary",Rules!$B$21,IF(E22="Rare",Rules!$B$20,IF(E22="Uncommon",Rules!$B$19,Rules!$B$18))))*IF(U22="Y",Rules!$B$22,1),2) -> 3 | AA22: =Y22-Z22 -> 0 | AB22: =IF(E22="Starter",IF(AA22<0,"Starter (under on purpose)","Starter too strong"),IF(ABS(AA22)<=Rules!$B$25,"Balanced",IF(AA22>0,"Over budget","Under budget"))) -> Balanced
A23: C19 | B23: Deep Breath | C23: Skill | D23: 0 | E23: Common | F23: Tactician | G23: Draw 1 card. Exhaust. | H23: Draw 2 cards. Exhaust. | M23: 1 | U23: Y | Y23: =ROUND((I23*Rules!$B$28+J23*Rules!$B$28*Rules!$B$24+K23*Rules!$B$29+L23*Rules!$B$30+M23*Rules!$B$31+N23*Rules!$B$32+(O23*Rules!$B$33+P23*Rules!$B$34+Q23*Rules!$B$35)*IF(R23="Y",Rules!$B$24,1)+S23*Rules!$B$36-T23*Rules!$B$37+IF(V23="Y",Rules!$B$38,0)+W23)*IF(C23="Power",Rules!$B$23,1),2) -> 4 | Z23: =ROUND((D23*Rules!$B$16+Rules!$B$17+IF(E23="Legendary",Rules!$B$21,IF(E23="Rare",Rules!$B$20,IF(E23="Uncommon",Rules!$B$19,Rules!$B$18))))*IF(U23="Y",Rules!$B$22,1),2) -> 3.9 | AA23: =Y23-Z23 -> 0.1 | AB23: =IF(E23="Starter",IF(AA23<0,"Starter (under on purpose)","Starter too strong"),IF(ABS(AA23)<=Rules!$B$25,"Balanced",IF(AA23>0,"Over budget","Under budget"))) -> Balanced
A24: C20 | B24: Stand Firm | C24: Skill | D24: 1 | E24: Common | F24: Guardian | G24: Gain 5 block. Apply 1 Weak. | H24: Gain 7 block. Apply 1 Weak. | K24: 5 | O24: 1 | Y24: =ROUND((I24*Rules!$B$28+J24*Rules!$B$28*Rules!$B$24+K24*Rules!$B$29+L24*Rules!$B$30+M24*Rules!$B$31+N24*Rules!$B$32+(O24*Rules!$B$33+P24*Rules!$B$34+Q24*Rules!$B$35)*IF(R24="Y",Rules!$B$24,1)+S24*Rules!$B$36-T24*Rules!$B$37+IF(V24="Y",Rules!$B$38,0)+W24)*IF(C24="Power",Rules!$B$23,1),2) -> 9 | Z24: =ROUND((D24*Rules!$B$16+Rules!$B$17+IF(E24="Legendary",Rules!$B$21,IF(E24="Rare",Rules!$B$20,IF(E24="Uncommon",Rules!$B$19,Rules!$B$18))))*IF(U24="Y",Rules!$B$22,1),2) -> 9 | AA24: =Y24-Z24 -> 0 | AB24: =IF(E24="Starter",IF(AA24<0,"Starter (under on purpose)","Starter too strong"),IF(ABS(AA24)<=Rules!$B$25,"Balanced",IF(AA24>0,"Over budget","Under budget"))) -> Balanced
A25: C21 | B25: Rope Swing | C25: Attack | D25: 1 | E25: Common | F25: Neutral | G25: Deal 5 damage. Gain 3 block. | H25: Deal 7 damage. Gain 4 block. | I25: 5 | K25: 3 | Y25: =ROUND((I25*Rules!$B$28+J25*Rules!$B$28*Rules!$B$24+K25*Rules!$B$29+L25*Rules!$B$30+M25*Rules!$B$31+N25*Rules!$B$32+(O25*Rules!$B$33+P25*Rules!$B$34+Q25*Rules!$B$35)*IF(R25="Y",Rules!$B$24,1)+S25*Rules!$B$36-T25*Rules!$B$37+IF(V25="Y",Rules!$B$38,0)+W25)*IF(C25="Power",Rules!$B$23,1),2) -> 8.6 | Z25: =ROUND((D25*Rules!$B$16+Rules!$B$17+IF(E25="Legendary",Rules!$B$21,IF(E25="Rare",Rules!$B$20,IF(E25="Uncommon",Rules!$B$19,Rules!$B$18))))*IF(U25="Y",Rules!$B$22,1),2) -> 9 | AA25: =Y25-Z25 -> -0.4 | AB25: =IF(E25="Starter",IF(AA25<0,"Starter (under on purpose)","Starter too strong"),IF(ABS(AA25)<=Rules!$B$25,"Balanced",IF(AA25>0,"Over budget","Under budget"))) -> Balanced
A26: C22 | B26: Torchlight | C26: Skill | D26: 1 | E26: Common | F26: Neutral | G26: Gain 3 block. Draw 1 card. Retain. | H26: Gain 5 block. Draw 1 card. Retain. | K26: 3 | M26: 1 | V26: Y | Y26: =ROUND((I26*Rules!$B$28+J26*Rules!$B$28*Rules!$B$24+K26*Rules!$B$29+L26*Rules!$B$30+M26*Rules!$B$31+N26*Rules!$B$32+(O26*Rules!$B$33+P26*Rules!$B$34+Q26*Rules!$B$35)*IF(R26="Y",Rules!$B$24,1)+S26*Rules!$B$36-T26*Rules!$B$37+IF(V26="Y",Rules!$B$38,0)+W26)*IF(C26="Power",Rules!$B$23,1),2) -> 9.6 | Z26: =ROUND((D26*Rules!$B$16+Rules!$B$17+IF(E26="Legendary",Rules!$B$21,IF(E26="Rare",Rules!$B$20,IF(E26="Uncommon",Rules!$B$19,Rules!$B$18))))*IF(U26="Y",Rules!$B$22,1),2) -> 9 | AA26: =Y26-Z26 -> 0.6 | AB26: =IF(E26="Starter",IF(AA26<0,"Starter (under on purpose)","Starter too strong"),IF(ABS(AA26)<=Rules!$B$25,"Balanced",IF(AA26>0,"Over budget","Under budget"))) -> Balanced
A27: C23 | B27: Rations | C27: Skill | D27: 1 | E27: Common | F27: Neutral | G27: Heal 5 HP. Draw 1 card. Exhaust. | H27: Heal 7 HP. Draw 1 card. Exhaust. | L27: 5 | M27: 1 | U27: Y | Y27: =ROUND((I27*Rules!$B$28+J27*Rules!$B$28*Rules!$B$24+K27*Rules!$B$29+L27*Rules!$B$30+M27*Rules!$B$31+N27*Rules!$B$32+(O27*Rules!$B$33+P27*Rules!$B$34+Q27*Rules!$B$35)*IF(R27="Y",Rules!$B$24,1)+S27*Rules!$B$36-T27*Rules!$B$37+IF(V27="Y",Rules!$B$38,0)+W27)*IF(C27="Power",Rules!$B$23,1),2) -> 11.5 | Z27: =ROUND((D27*Rules!$B$16+Rules!$B$17+IF(E27="Legendary",Rules!$B$21,IF(E27="Rare",Rules!$B$20,IF(E27="Uncommon",Rules!$B$19,Rules!$B$18))))*IF(U27="Y",Rules!$B$22,1),2) -> 11.7 | AA27: =Y27-Z27 -> -0.2 | AB27: =IF(E27="Starter",IF(AA27<0,"Starter (under on purpose)","Starter too strong"),IF(ABS(AA27)<=Rules!$B$25,"Balanced",IF(AA27>0,"Over budget","Under budget"))) -> Balanced
A28: C24 | B28: Crossbow Bolt | C28: Attack | D28: 2 | E28: Common | F28: Neutral | G28: Deal 12 damage. Apply 1 Weak. | H28: Deal 16 damage. Apply 1 Weak. | I28: 12 | O28: 1 | Y28: =ROUND((I28*Rules!$B$28+J28*Rules!$B$28*Rules!$B$24+K28*Rules!$B$29+L28*Rules!$B$30+M28*Rules!$B$31+N28*Rules!$B$32+(O28*Rules!$B$33+P28*Rules!$B$34+Q28*Rules!$B$35)*IF(R28="Y",Rules!$B$24,1)+S28*Rules!$B$36-T28*Rules!$B$37+IF(V28="Y",Rules!$B$38,0)+W28)*IF(C28="Power",Rules!$B$23,1),2) -> 15 | Z28: =ROUND((D28*Rules!$B$16+Rules!$B$17+IF(E28="Legendary",Rules!$B$21,IF(E28="Rare",Rules!$B$20,IF(E28="Uncommon",Rules!$B$19,Rules!$B$18))))*IF(U28="Y",Rules!$B$22,1),2) -> 15 | AA28: =Y28-Z28 -> 0 | AB28: =IF(E28="Starter",IF(AA28<0,"Starter (under on purpose)","Starter too strong"),IF(ABS(AA28)<=Rules!$B$25,"Balanced",IF(AA28>0,"Over budget","Under budget"))) -> Balanced
A29: C25 | B29: Warm Up | C29: Attack | D29: 1 | E29: Common | F29: Brawler | G29: Deal 5 damage. Gain 1 Strength. | H29: Deal 7 damage. Gain 1 Strength. | I29: 5 | S29: 1 | Y29: =ROUND((I29*Rules!$B$28+J29*Rules!$B$28*Rules!$B$24+K29*Rules!$B$29+L29*Rules!$B$30+M29*Rules!$B$31+N29*Rules!$B$32+(O29*Rules!$B$33+P29*Rules!$B$34+Q29*Rules!$B$35)*IF(R29="Y",Rules!$B$24,1)+S29*Rules!$B$36-T29*Rules!$B$37+IF(V29="Y",Rules!$B$38,0)+W29)*IF(C29="Power",Rules!$B$23,1),2) -> 9 | Z29: =ROUND((D29*Rules!$B$16+Rules!$B$17+IF(E29="Legendary",Rules!$B$21,IF(E29="Rare",Rules!$B$20,IF(E29="Uncommon",Rules!$B$19,Rules!$B$18))))*IF(U29="Y",Rules!$B$22,1),2) -> 9 | AA29: =Y29-Z29 -> 0 | AB29: =IF(E29="Starter",IF(AA29<0,"Starter (under on purpose)","Starter too strong"),IF(ABS(AA29)<=Rules!$B$25,"Balanced",IF(AA29>0,"Over budget","Under budget"))) -> Balanced
A30: C26 | B30: Uppercut | C30: Attack | D30: 1 | E30: Common | F30: Brawler | G30: Deal 6 damage. Apply 1 Weak. | H30: Deal 8 damage. Apply 2 Weak. | I30: 6 | O30: 1 | Y30: =ROUND((I30*Rules!$B$28+J30*Rules!$B$28*Rules!$B$24+K30*Rules!$B$29+L30*Rules!$B$30+M30*Rules!$B$31+N30*Rules!$B$32+(O30*Rules!$B$33+P30*Rules!$B$34+Q30*Rules!$B$35)*IF(R30="Y",Rules!$B$24,1)+S30*Rules!$B$36-T30*Rules!$B$37+IF(V30="Y",Rules!$B$38,0)+W30)*IF(C30="Power",Rules!$B$23,1),2) -> 9 | Z30: =ROUND((D30*Rules!$B$16+Rules!$B$17+IF(E30="Legendary",Rules!$B$21,IF(E30="Rare",Rules!$B$20,IF(E30="Uncommon",Rules!$B$19,Rules!$B$18))))*IF(U30="Y",Rules!$B$22,1),2) -> 9 | AA30: =Y30-Z30 -> 0 | AB30: =IF(E30="Starter",IF(AA30<0,"Starter (under on purpose)","Starter too strong"),IF(ABS(AA30)<=Rules!$B$25,"Balanced",IF(AA30>0,"Over budget","Under budget"))) -> Balanced
A31: C27 | B31: Flurry | C31: Attack | D31: 1 | E31: Common | F31: Brawler | G31: Deal 2 damage 4 times. | H31: Deal 3 damage 4 times. | I31: 8 | W31: 1 | X31: Other: 4 hits quadruple Strength bonus | Y31: =ROUND((I31*Rules!$B$28+J31*Rules!$B$28*Rules!$B$24+K31*Rules!$B$29+L31*Rules!$B$30+M31*Rules!$B$31+N31*Rules!$B$32+(O31*Rules!$B$33+P31*Rules!$B$34+Q31*Rules!$B$35)*IF(R31="Y",Rules!$B$24,1)+S31*Rules!$B$36-T31*Rules!$B$37+IF(V31="Y",Rules!$B$38,0)+W31)*IF(C31="Power",Rules!$B$23,1),2) -> 9 | Z31: =ROUND((D31*Rules!$B$16+Rules!$B$17+IF(E31="Legendary",Rules!$B$21,IF(E31="Rare",Rules!$B$20,IF(E31="Uncommon",Rules!$B$19,Rules!$B$18))))*IF(U31="Y",Rules!$B$22,1),2) -> 9 | AA31: =Y31-Z31 -> 0 | AB31: =IF(E31="Starter",IF(AA31<0,"Starter (under on purpose)","Starter too strong"),IF(ABS(AA31)<=Rules!$B$25,"Balanced",IF(AA31>0,"Over budget","Under budget"))) -> Balanced
A32: C28 | B32: Double Tap | C32: Attack | D32: 0 | E32: Common | F32: Brawler | G32: Deal 2 damage twice. | H32: Deal 3 damage twice. | I32: 4 | X32: Multi-hit; pairs with Strength | Y32: =ROUND((I32*Rules!$B$28+J32*Rules!$B$28*Rules!$B$24+K32*Rules!$B$29+L32*Rules!$B$30+M32*Rules!$B$31+N32*Rules!$B$32+(O32*Rules!$B$33+P32*Rules!$B$34+Q32*Rules!$B$35)*IF(R32="Y",Rules!$B$24,1)+S32*Rules!$B$36-T32*Rules!$B$37+IF(V32="Y",Rules!$B$38,0)+W32)*IF(C32="Power",Rules!$B$23,1),2) -> 4 | Z32: =ROUND((D32*Rules!$B$16+Rules!$B$17+IF(E32="Legendary",Rules!$B$21,IF(E32="Rare",Rules!$B$20,IF(E32="Uncommon",Rules!$B$19,Rules!$B$18))))*IF(U32="Y",Rules!$B$22,1),2) -> 3 | AA32: =Y32-Z32 -> 1 | AB32: =IF(E32="Starter",IF(AA32<0,"Starter (under on purpose)","Starter too strong"),IF(ABS(AA32)<=Rules!$B$25,"Balanced",IF(AA32>0,"Over budget","Under budget"))) -> Balanced
A33: C29 | B33: Charge | C33: Attack | D33: 2 | E33: Common | F33: Brawler | G33: Deal 10 damage. Gain 1 Strength. | H33: Deal 13 damage. Gain 1 Strength. | I33: 10 | S33: 1 | Y33: =ROUND((I33*Rules!$B$28+J33*Rules!$B$28*Rules!$B$24+K33*Rules!$B$29+L33*Rules!$B$30+M33*Rules!$B$31+N33*Rules!$B$32+(O33*Rules!$B$33+P33*Rules!$B$34+Q33*Rules!$B$35)*IF(R33="Y",Rules!$B$24,1)+S33*Rules!$B$36-T33*Rules!$B$37+IF(V33="Y",Rules!$B$38,0)+W33)*IF(C33="Power",Rules!$B$23,1),2) -> 14 | Z33: =ROUND((D33*Rules!$B$16+Rules!$B$17+IF(E33="Legendary",Rules!$B$21,IF(E33="Rare",Rules!$B$20,IF(E33="Uncommon",Rules!$B$19,Rules!$B$18))))*IF(U33="Y",Rules!$B$22,1),2) -> 15 | AA33: =Y33-Z33 -> -1 | AB33: =IF(E33="Starter",IF(AA33<0,"Starter (under on purpose)","Starter too strong"),IF(ABS(AA33)<=Rules!$B$25,"Balanced",IF(AA33>0,"Over budget","Under budget"))) -> Balanced
A34: C30 | B34: Rage Fist | C34: Attack | D34: 1 | E34: Common | F34: Brawler | G34: Deal 10 damage. Lose 1 HP. | H34: Deal 13 damage. Lose 1 HP. | I34: 10 | T34: 1 | Y34: =ROUND((I34*Rules!$B$28+J34*Rules!$B$28*Rules!$B$24+K34*Rules!$B$29+L34*Rules!$B$30+M34*Rules!$B$31+N34*Rules!$B$32+(O34*Rules!$B$33+P34*Rules!$B$34+Q34*Rules!$B$35)*IF(R34="Y",Rules!$B$24,1)+S34*Rules!$B$36-T34*Rules!$B$37+IF(V34="Y",Rules!$B$38,0)+W34)*IF(C34="Power",Rules!$B$23,1),2) -> 8.5 | Z34: =ROUND((D34*Rules!$B$16+Rules!$B$17+IF(E34="Legendary",Rules!$B$21,IF(E34="Rare",Rules!$B$20,IF(E34="Uncommon",Rules!$B$19,Rules!$B$18))))*IF(U34="Y",Rules!$B$22,1),2) -> 9 | AA34: =Y34-Z34 -> -0.5 | AB34: =IF(E34="Starter",IF(AA34<0,"Starter (under on purpose)","Starter too strong"),IF(ABS(AA34)<=Rules!$B$25,"Balanced",IF(AA34>0,"Over budget","Under budget"))) -> Balanced
A35: C31 | B35: Grit Teeth | C35: Skill | D35: 1 | E35: Common | F35: Brawler | G35: Gain 4 block. Gain 1 Strength. | H35: Gain 6 block. Gain 1 Strength. | K35: 4 | S35: 1 | Y35: =ROUND((I35*Rules!$B$28+J35*Rules!$B$28*Rules!$B$24+K35*Rules!$B$29+L35*Rules!$B$30+M35*Rules!$B$31+N35*Rules!$B$32+(O35*Rules!$B$33+P35*Rules!$B$34+Q35*Rules!$B$35)*IF(R35="Y",Rules!$B$24,1)+S35*Rules!$B$36-T35*Rules!$B$37+IF(V35="Y",Rules!$B$38,0)+W35)*IF(C35="Power",Rules!$B$23,1),2) -> 8.8 | Z35: =ROUND((D35*Rules!$B$16+Rules!$B$17+IF(E35="Legendary",Rules!$B$21,IF(E35="Rare",Rules!$B$20,IF(E35="Uncommon",Rules!$B$19,Rules!$B$18))))*IF(U35="Y",Rules!$B$22,1),2) -> 9 | AA35: =Y35-Z35 -> -0.2 | AB35: =IF(E35="Starter",IF(AA35<0,"Starter (under on purpose)","Starter too strong"),IF(ABS(AA35)<=Rules!$B$25,"Balanced",IF(AA35>0,"Over budget","Under budget"))) -> Balanced
A36: C32 | B36: Wild Swing | C36: Attack | D36: 1 | E36: Common | F36: Brawler | G36: Deal 12 damage to a random enemy. | H36: Deal 16 damage to a random enemy. | I36: 12 | W36: -3 | X36: Other: random target is a drawback | Y36: =ROUND((I36*Rules!$B$28+J36*Rules!$B$28*Rules!$B$24+K36*Rules!$B$29+L36*Rules!$B$30+M36*Rules!$B$31+N36*Rules!$B$32+(O36*Rules!$B$33+P36*Rules!$B$34+Q36*Rules!$B$35)*IF(R36="Y",Rules!$B$24,1)+S36*Rules!$B$36-T36*Rules!$B$37+IF(V36="Y",Rules!$B$38,0)+W36)*IF(C36="Power",Rules!$B$23,1),2) -> 9 | Z36: =ROUND((D36*Rules!$B$16+Rules!$B$17+IF(E36="Legendary",Rules!$B$21,IF(E36="Rare",Rules!$B$20,IF(E36="Uncommon",Rules!$B$19,Rules!$B$18))))*IF(U36="Y",Rules!$B$22,1),2) -> 9 | AA36: =Y36-Z36 -> 0 | AB36: =IF(E36="Starter",IF(AA36<0,"Starter (under on purpose)","Starter too strong"),IF(ABS(AA36)<=Rules!$B$25,"Balanced",IF(AA36>0,"Over budget","Under budget"))) -> Balanced
A37: C33 | B37: Hunker Down | C37: Skill | D37: 1 | E37: Common | F37: Guardian | G37: Gain 6 block. Retain. | H37: Gain 8 block. Retain. | K37: 6 | V37: Y | Y37: =ROUND((I37*Rules!$B$28+J37*Rules!$B$28*Rules!$B$24+K37*Rules!$B$29+L37*Rules!$B$30+M37*Rules!$B$31+N37*Rules!$B$32+(O37*Rules!$B$33+P37*Rules!$B$34+Q37*Rules!$B$35)*IF(R37="Y",Rules!$B$24,1)+S37*Rules!$B$36-T37*Rules!$B$37+IF(V37="Y",Rules!$B$38,0)+W37)*IF(C37="Power",Rules!$B$23,1),2) -> 9.2 | Z37: =ROUND((D37*Rules!$B$16+Rules!$B$17+IF(E37="Legendary",Rules!$B$21,IF(E37="Rare",Rules!$B$20,IF(E37="Uncommon",Rules!$B$19,Rules!$B$18))))*IF(U37="Y",Rules!$B$22,1),2) -> 9 | AA37: =Y37-Z37 -> 0.2 | AB37: =IF(E37="Starter",IF(AA37<0,"Starter (under on purpose)","Starter too strong"),IF(ABS(AA37)<=Rules!$B$25,"Balanced",IF(AA37>0,"Over budget","Under budget"))) -> Balanced
A38: C34 | B38: Buckler Bash | C38: Attack | D38: 1 | E38: Common | F38: Guardian | G38: Deal damage equal to your block. | H38: Costs 0. Deal damage equal to your block. | W38: 8 | X38: NEW: damage_equals_block. PLAYTEST: value ~ typical block (8) | Y38: =ROUND((I38*Rules!$B$28+J38*Rules!$B$28*Rules!$B$24+K38*Rules!$B$29+L38*Rules!$B$30+M38*Rules!$B$31+N38*Rules!$B$32+(O38*Rules!$B$33+P38*Rules!$B$34+Q38*Rules!$B$35)*IF(R38="Y",Rules!$B$24,1)+S38*Rules!$B$36-T38*Rules!$B$37+IF(V38="Y",Rules!$B$38,0)+W38)*IF(C38="Power",Rules!$B$23,1),2) -> 8 | Z38: =ROUND((D38*Rules!$B$16+Rules!$B$17+IF(E38="Legendary",Rules!$B$21,IF(E38="Rare",Rules!$B$20,IF(E38="Uncommon",Rules!$B$19,Rules!$B$18))))*IF(U38="Y",Rules!$B$22,1),2) -> 9 | AA38: =Y38-Z38 -> -1 | AB38: =IF(E38="Starter",IF(AA38<0,"Starter (under on purpose)","Starter too strong"),IF(ABS(AA38)<=Rules!$B$25,"Balanced",IF(AA38>0,"Over budget","Under budget"))) -> Balanced
A39: C35 | B39: Shield Wall | C39: Skill | D39: 2 | E39: Common | F39: Guardian | G39: Gain 9 block. Apply 1 Weak to ALL enemies. | H39: Gain 12 block. Apply 1 Weak to ALL enemies. | K39: 9 | O39: 1 | R39: Y | Y39: =ROUND((I39*Rules!$B$28+J39*Rules!$B$28*Rules!$B$24+K39*Rules!$B$29+L39*Rules!$B$30+M39*Rules!$B$31+N39*Rules!$B$32+(O39*Rules!$B$33+P39*Rules!$B$34+Q39*Rules!$B$35)*IF(R39="Y",Rules!$B$24,1)+S39*Rules!$B$36-T39*Rules!$B$37+IF(V39="Y",Rules!$B$38,0)+W39)*IF(C39="Power",Rules!$B$23,1),2) -> 15.3 | Z39: =ROUND((D39*Rules!$B$16+Rules!$B$17+IF(E39="Legendary",Rules!$B$21,IF(E39="Rare",Rules!$B$20,IF(E39="Uncommon",Rules!$B$19,Rules!$B$18))))*IF(U39="Y",Rules!$B$22,1),2) -> 15 | AA39: =Y39-Z39 -> 0.3 | AB39: =IF(E39="Starter",IF(AA39<0,"Starter (under on purpose)","Starter too strong"),IF(ABS(AA39)<=Rules!$B$25,"Balanced",IF(AA39>0,"Over budget","Under budget"))) -> Balanced
A40: C36 | B40: Fortify | C40: Skill | D40: 0 | E40: Common | F40: Guardian | G40: Gain 3 block. | H40: Gain 5 block. | K40: 3 | Y40: =ROUND((I40*Rules!$B$28+J40*Rules!$B$28*Rules!$B$24+K40*Rules!$B$29+L40*Rules!$B$30+M40*Rules!$B$31+N40*Rules!$B$32+(O40*Rules!$B$33+P40*Rules!$B$34+Q40*Rules!$B$35)*IF(R40="Y",Rules!$B$24,1)+S40*Rules!$B$36-T40*Rules!$B$37+IF(V40="Y",Rules!$B$38,0)+W40)*IF(C40="Power",Rules!$B$23,1),2) -> 3.6 | Z40: =ROUND((D40*Rules!$B$16+Rules!$B$17+IF(E40="Legendary",Rules!$B$21,IF(E40="Rare",Rules!$B$20,IF(E40="Uncommon",Rules!$B$19,Rules!$B$18))))*IF(U40="Y",Rules!$B$22,1),2) -> 3 | AA40: =Y40-Z40 -> 0.6 | AB40: =IF(E40="Starter",IF(AA40<0,"Starter (under on purpose)","Starter too strong"),IF(ABS(AA40)<=Rules!$B$25,"Balanced",IF(AA40>0,"Over budget","Under budget"))) -> Balanced
...

Sheet Summary
A1: Set Summary
A3: Archetype | B3: Starter | C3: Common | D3: Uncommon | E3: Rare | F3: Legendary | G3: Total
A4: Neutral | B4: =COUNTIFS(Cards!$F$2:$F$400,$A4,Cards!$E$2:$E$400,B$3) -> 3 | C4: =COUNTIFS(Cards!$F$2:$F$400,$A4,Cards!$E$2:$E$400,C$3) -> 7 | D4: =COUNTIFS(Cards!$F$2:$F$400,$A4,Cards!$E$2:$E$400,D$3) -> 3 | E4: =COUNTIFS(Cards!$F$2:$F$400,$A4,Cards!$E$2:$E$400,E$3) -> 3 | F4: =COUNTIFS(Cards!$F$2:$F$400,$A4,Cards!$E$2:$E$400,F$3) -> 0 | G4: =SUM(B4:F4) -> 16
A5: Brawler | B5: =COUNTIFS(Cards!$F$2:$F$400,$A5,Cards!$E$2:$E$400,B$3) -> 0 | C5: =COUNTIFS(Cards!$F$2:$F$400,$A5,Cards!$E$2:$E$400,C$3) -> 12 | D5: =COUNTIFS(Cards!$F$2:$F$400,$A5,Cards!$E$2:$E$400,D$3) -> 9 | E5: =COUNTIFS(Cards!$F$2:$F$400,$A5,Cards!$E$2:$E$400,E$3) -> 5 | F5: =COUNTIFS(Cards!$F$2:$F$400,$A5,Cards!$E$2:$E$400,F$3) -> 2 | G5: =SUM(B5:F5) -> 28
A6: Guardian | B6: =COUNTIFS(Cards!$F$2:$F$400,$A6,Cards!$E$2:$E$400,B$3) -> 0 | C6: =COUNTIFS(Cards!$F$2:$F$400,$A6,Cards!$E$2:$E$400,C$3) -> 13 | D6: =COUNTIFS(Cards!$F$2:$F$400,$A6,Cards!$E$2:$E$400,D$3) -> 9 | E6: =COUNTIFS(Cards!$F$2:$F$400,$A6,Cards!$E$2:$E$400,E$3) -> 4 | F6: =COUNTIFS(Cards!$F$2:$F$400,$A6,Cards!$E$2:$E$400,F$3) -> 2 | G6: =SUM(B6:F6) -> 28
A7: Venom | B7: =COUNTIFS(Cards!$F$2:$F$400,$A7,Cards!$E$2:$E$400,B$3) -> 0 | C7: =COUNTIFS(Cards!$F$2:$F$400,$A7,Cards!$E$2:$E$400,C$3) -> 11 | D7: =COUNTIFS(Cards!$F$2:$F$400,$A7,Cards!$E$2:$E$400,D$3) -> 10 | E7: =COUNTIFS(Cards!$F$2:$F$400,$A7,Cards!$E$2:$E$400,E$3) -> 5 | F7: =COUNTIFS(Cards!$F$2:$F$400,$A7,Cards!$E$2:$E$400,F$3) -> 2 | G7: =SUM(B7:F7) -> 28
A8: Tactician | B8: =COUNTIFS(Cards!$F$2:$F$400,$A8,Cards!$E$2:$E$400,B$3) -> 0 | C8: =COUNTIFS(Cards!$F$2:$F$400,$A8,Cards!$E$2:$E$400,C$3) -> 12 | D8: =COUNTIFS(Cards!$F$2:$F$400,$A8,Cards!$E$2:$E$400,D$3) -> 9 | E8: =COUNTIFS(Cards!$F$2:$F$400,$A8,Cards!$E$2:$E$400,E$3) -> 5 | F8: =COUNTIFS(Cards!$F$2:$F$400,$A8,Cards!$E$2:$E$400,F$3) -> 2 | G8: =SUM(B8:F8) -> 28
A9: Total | B9: =SUM(B4:B8) -> 3 | C9: =SUM(C4:C8) -> 55 | D9: =SUM(D4:D8) -> 40 | E9: =SUM(E4:E8) -> 22 | F9: =SUM(F4:F8) -> 8 | G9: =SUM(G4:G8) -> 128
A11: Balance status
A12: Balanced | B12: =COUNTIF(Cards!$AB$2:$AB$400,A12) -> 125
A13: Over budget | B13: =COUNTIF(Cards!$AB$2:$AB$400,A13) -> 0
A14: Under budget | B14: =COUNTIF(Cards!$AB$2:$AB$400,A14) -> 0
A15: Starter (under on purpose) | B15: =COUNTIF(Cards!$AB$2:$AB$400,A15) -> 3
A17: Type (excluding starters)
A18: Attack | B18: =COUNTIFS(Cards!$C$2:$C$400,A18,Cards!$E$2:$E$400,"<>Starter") -> 46
A19: Skill | B19: =COUNTIFS(Cards!$C$2:$C$400,A19,Cards!$E$2:$E$400,"<>Starter") -> 63
A20: Power | B20: =COUNTIFS(Cards!$C$2:$C$400,A20,Cards!$E$2:$E$400,"<>Starter") -> 16
A22: Starter deck
A23: Strike | B23: 5
A24: Defend | B24: 4
A25: Lantern Bash | B25: 1
A26: Total | B26: =SUM(B23:B25) -> 10
A28: Reward odds per card offered (normal fights)
A29: Common | B29: 0.6
A30: Uncommon | B30: 0.31
A31: Rare | B31: 0.07
A32: Legendary | B32: 0.02
A33: Total | B33: =SUM(B29:B32) -> 1
A35: Elite and boss rewards
A36: After an elite or the boss, one of the 3 choices is always a Legendary the player doesn't own (Unique: max 1 copy per deck).

Sheet Keywords
A1: Keywords (show as tap-to-explain on cards)
A3: Keyword | B3: Rule | C3: Who implements
A4: Block | B4: Prevents damage. All block is removed at the start of your next turn. | C4: Role 1
A5: Heal | B5: Restore HP, up to max HP. | C5: Role 1
A6: Poison | B6: At the start of the poisoned creature's turn, it loses HP equal to its Poison, then Poison goes down by 1. | C6: Role 1
A7: Weak | B7: Deals 25% less attack damage. Lasts the listed number of turns. | C7: Role 1
A8: Vulnerable | B8: Takes 50% more attack damage. Lasts the listed number of turns. | C8: Role 1
A9: Strength | B9: Each attack hit deals +1 damage per Strength. Lasts the whole fight. | C9: Role 1
A10: Exhaust | B10: After playing, remove this card from your deck for the rest of the fight (it returns next fight). | C10: Role 2
A11: Power | B11: Stays in play for the rest of the fight instead of going to the discard pile. | C11: Role 2
A12: ALL enemies | B12: Hits every enemy in the fight. | C12: Role 1
A13: Intent | B13: Enemies show what they'll do next turn. Some cards (Parry, Rebuke) check it. | C13: Role 1 + Role 3
A14: Discard | B14: Choose a card from your hand to put in the discard pile. | C14: Role 2 + Role 3
... A17: Invulnerable | B17: NEW. You take no damage until your next turn. | C17: Role 1

Sheet New Mechanics
A1: New mechanics in the alpha set (for the code phase)
A2: Commons and Uncommons use only 7 of these; most are on Rares and Legendaries.
A4: Mechanic / code op | B4: What it does | C4: Cards that use it | D4: Who implements
A5: Retain (keyword) | B5: Card stays in hand at end of turn. | C5: Torchlight, Hunker Down, Poison Shank, Prepared Strike, Deflect, Stone Skin, Bottled Plague, Battle Rhythm, Momentum, Battle Plan | D5: Role 2
A6: Unique (keyword) | B6: Max one copy per deck; reward generator skips Uniques you own. | C6: All 8 Legendaries | D6: Role 2 + Role 4
A7: Legendary rarity | B7: +6 budget; 2% reward odds; guaranteed choice after elites/boss. | C7: All 8 Legendaries | D7: Role 2 + Role 4
A8: damage_equals_block | B8: Deal damage equal to your current block. | C8: Buckler Bash | D8: Role 1
A9: if_intent on a status | B9: Apply a status only if the enemy intends to attack. | C9: Rebuke | D9: Role 1
A10: energy_next_turn | B10: Gain energy at the start of your next turn. | C10: Tactical Retreat, Battle Rhythm | D10: Role 1
A11: multiply_block | B11: Multiply your current block. | C11: Entrench | D11: Role 1
A12: bonus_if_status | B12: Extra damage if the target has a status. | C12: Bane (Poison), Exploit Weakness (Vulnerable) | D12: Role 1
A13: damage_equals_status | B13: Deal damage equal to the target's Poison. | C13: Venom Burst | D13: Role 1
A14: power: draw_per_turn | B14: Draw extra cards at the start of each turn. | C14: Map of the Depths, Explorer's Kit, Grand Strategist | D14: Role 1 + Role 2
A15: power: strength_per_turn | B15: Gain Strength at the start of each turn. | C15: Bloodlust | D15: Role 1
... A24: Reused existing effects | B24: No new code: multiply_status (Limit Break, Pandemic, Plaguebearer's Kiss), random_enemy target (Wild Swing), Black Plague at a lower amount (Toxic Aura), Iron Skin/Berserker Rage on new Powers. | C24: Several | D24: —
